File: Code/Example GUIs/Stress-Strain analyzer/SS_Data/304/304-3d1.txt
*
POSN mm 	LOAD kn	STRAIN1 %	STRAIN2 %	STRESS(MPA)	TIME(sec)
13.472883	0.017195	-1.765399	-0.006024	0.781612	0.000000
13.502512	0.315250	-1.765399	-0.003569	14.329562	3.000000
13.532141	0.992648	-1.765399	0.008990	45.120356	6.000000
13.561771	1.870138	-1.765399	0.029198	85.006278	9.000000
13.591400	2.747628	-1.765773	0.051484	124.892199	12.000000
13.629494	3.476091	-1.765399	0.073534	158.004145	15.000000
13.652775	4.361919	-1.765399	0.102760	198.269030	18.000000
13.682404	5.037753	-1.765399	0.130806	228.988769	21.000000
13.714149	5.552054	-1.765399	0.160646	252.366087	24.000000
13.743779	6.072087	-1.765399	0.198041	276.003943	27.000000
13.773408	6.451950	-1.765399	0.241006	293.270473	30.000000
13.800921	6.790128	-1.765399	0.295210	308.642185	33.000000
13.832666	6.949577	-1.765399	0.354134	315.889864	36.000000
13.862295	7.209072	-1.765773	0.430718	327.685107	39.000000
13.891925	7.324751	-1.765399	0.506546	332.943227	42.000000
13.921554	7.558193	-1.765399	0.591533	343.554209	45.000000
13.953299	7.690546	-1.765399	0.682187	349.570256	48.000000
13.982928	7.754117	-1.765399	0.779261	352.459854	51.000000
14.012558	7.894286	-1.765399	0.880349	358.831180	54.000000
14.042187	7.975053	-1.765399	0.980071	362.502390	57.000000
14.071816	8.075099	-1.765399	1.086777	367.049953	60.000000
14.103562	8.018302	-1.765399	1.189518	364.468264	63.000000
14.131074	8.181398	-1.765399	1.304534	371.881739	66.000000
14.171286	8.080831	-1.765960	1.401420	367.310491	69.000000
14.192449	8.318441	-1.765773	1.512282	378.110954	72.000000
14.222078	8.347100	-1.765399	1.621444	379.413641	75.000000
14.251708	8.448189	-1.765399	1.735327	384.008575	78.000000
14.283453	8.510197	-1.765399	1.846751	386.827117	81.000000
14.313082	8.580021	-1.765399	1.956290	390.000938	84.000000
14.342712	8.636818	-1.765399	2.067152	392.582627	87.000000
14.370224	8.585231	-1.765399	2.177258	390.237790	90.000000
14.401970	8.700389	-1.765399	2.294352	395.472225	93.000000
14.433716	8.725401	-1.765399	2.405780	396.609116	96.000000
14.461228	8.788972	-1.765399	2.510787	399.498713	99.000000
14.490858	8.785845	-1.765773	2.619005	399.356602	102.000000
14.522603	8.875991	-1.765399	2.732888	403.454146	105.000000
14.552232	8.909861	-1.765399	2.843183	404.993686	108.000000
14.581862	9.007302	-1.765399	2.947813	409.422823	111.000000
14.611491	8.973432	-1.765399	3.056219	407.883284	114.000000
14.645353	8.989064	-1.765399	3.167081	408.593840	117.000000
14.670749	9.105785	-1.765399	3.279075	413.899331	120.000000
14.702495	9.114122	-1.765212	3.385593	414.278295	123.000000
14.732124	9.180299	-1.765773	3.488334	417.286318	126.000000
14.763869	9.182383	-1.765773	3.596363	417.381059	129.000000
14.791382	9.248560	-1.765399	3.702574	420.389083	132.000000
14.821011	9.270445	-1.765399	3.808337	421.383863	135.000000
14.852757	9.359549	-1.765399	3.912588	425.434036	138.000000
14.882386	9.296499	-1.765773	4.016840	422.568124	141.000000
14.912015	9.338185	-1.765399	4.125624	424.462942	144.000000
14.941645	9.421557	-1.765399	4.233275	428.252578	147.000000
14.971274	9.486170	-1.765773	4.340170	431.189546	150.000000
15.003019	9.526814	-1.765773	4.439889	433.036994	153.000000
15.030532	9.528898	-1.765399	4.545652	433.131735	156.000000
15.062278	9.586216	-1.765773	4.650281	435.737110	159.000000
15.094023	9.604975	-1.765960	4.754910	436.589778	162.000000
15.121536	9.715443	-1.765773	4.855384	441.611046	165.000000
15.153282	9.634155	-1.765773	4.961524	437.916151	168.000000
15.180795	9.693558	-1.765399	5.069175	440.616266	171.000000
15.212540	9.724301	-1.765773	5.172671	442.013695	174.000000
15.237937	9.664378	-1.765399	5.268235	439.289894	177.000000
15.271799	9.800274	-1.765399	5.370976	445.467001	180.000000
15.301428	9.846129	-1.765399	5.477116	447.551301	183.000000
15.331057	9.903447	-1.765773	5.579479	450.156676	186.000000
15.360686	9.934711	-1.766147	5.684108	451.577789	189.000000
15.390315	9.969102	-1.765399	5.781560	453.141014	192.000000
15.419945	9.902405	-1.765773	5.888078	450.109305	195.000000
15.451690	10.004535	-1.765399	5.995351	454.751610	198.000000
15.481319	10.023294	-1.765399	6.098092	455.604278	201.000000
15.508832	10.069149	-1.765399	6.201588	457.688578	204.000000
15.542694	10.071233	-1.765399	6.297530	457.783319	207.000000
15.572323	10.129593	-1.765399	6.403292	460.436064	210.000000
15.601952	10.146268	-1.765399	6.505277	461.193991	213.000000
15.631582	10.196291	-1.765773	6.608396	463.467773	216.000000
15.661211	10.142099	-1.765399	6.702071	461.004509	219.000000
15.695073	10.233808	-1.765399	6.813499	465.173109	222.000000
15.720469	10.303632	-1.765399	6.917373	468.346930	225.000000
15.752215	10.319265	-1.765773	7.018225	469.057486	228.000000
15.781844	10.357824	-1.765399	7.120210	470.810193	231.000000
15.811473	10.348445	-1.765773	7.218418	470.383859	234.000000
15.841102	10.400552	-1.765399	7.319647	472.752382	237.000000
15.870732	10.417227	-1.765773	7.420877	473.510309	240.000000
15.900361	10.468292	-1.765399	7.522107	475.831461	243.000000
15.932106	10.374499	-1.765399	7.615782	471.568120	246.000000
15.965968	10.500599	-1.765399	7.726077	477.299945	249.000000
15.991365	10.529779	-1.765399	7.825796	478.626318	252.000000
16.020994	10.590224	-1.765399	7.928914	481.373804	255.000000
16.050623	10.606898	-1.765399	8.028255	482.131731	258.000000
16.082369	10.631910	-1.765399	8.124952	483.268622	261.000000
16.111998	10.669427	-1.765399	8.226182	484.973958	264.000000
16.141627	10.696523	-1.765586	8.324390	486.205590	267.000000
16.171256	10.731956	-1.765399	8.424864	487.816186	270.000000
16.203002	10.646500	-1.765399	8.518539	483.931808	273.000000
16.228398	10.756968	-1.765960	8.624302	488.953076	276.000000
16.262260	10.769473	-1.765960	8.724776	489.521522	279.000000
16.291890	10.816370	-1.765399	8.823739	491.653192	282.000000
16.321519	10.806991	-1.765399	8.922703	491.226858	285.000000
16.351148	10.873688	-1.766147	9.013356	494.258567	288.000000
16.380777	10.890363	-1.765399	9.113075	495.016494	291.000000
16.410406	10.950808	-1.765399	9.210905	497.763981	294.000000
16.440036	10.941428	-1.765773	9.308735	497.337647	297.000000
16.473897	10.877857	-1.765399	9.403922	494.448049	300.000000
16.501410	11.004999	-1.765399	9.508929	500.227244	303.000000
16.531039	11.015421	-1.765773	9.606003	500.700949	306.000000
16.562785	11.057107	-1.765399	9.704211	502.595767	309.000000
16.590298	11.040432	-1.765399	9.802041	501.837840	312.000000
16.619927	11.095666	-1.765773	9.895717	504.348474	315.000000
16.649556	11.098793	-1.765399	9.993169	504.490585	318.000000
16.679185	11.160280	-1.765399	10.089866	507.285442	321.000000
16.710931	11.105046	-1.765399	10.185052	504.774808	324.000000
16.736328	11.095666	-1.765399	10.283260	504.348474	327.000000
16.770189	11.226977	-1.765399	10.383734	510.317151	330.000000
16.801935	11.250947	-1.765399	10.481187	511.406671	333.000000
16.829448	11.290548	-1.765399	10.577128	513.206748	336.000000
16.859077	11.269705	-1.765773	10.674581	512.259339	339.000000
16.890823	11.327024	-1.766147	10.765990	514.864714	342.000000
16.920452	11.323897	-1.765399	10.863442	514.722603	345.000000
16.952197	11.386426	-1.765399	10.959762	517.564830	348.000000
16.981827	11.299928	-1.765773	11.053437	513.633082	351.000000
17.007223	11.316602	-1.765399	11.150512	514.391010	354.000000
17.041085	11.407269	-1.765773	11.248720	518.512239	357.000000
17.070714	11.452082	-1.765399	11.344661	520.549168	360.000000
17.100343	11.463545	-1.765773	11.440603	521.070243	363.000000
17.129973	11.484388	-1.765399	11.537677	522.017653	366.000000
17.159602	11.543791	-1.765399	11.627953	524.717768	369.000000
17.189231	11.557339	-1.765399	11.722384	525.333584	372.000000
17.220977	11.609446	-1.765399	11.817948	527.702107	375.000000
17.252722	11.507316	-1.765773	11.914267	523.059802	378.000000
17.286584	11.549002	-1.765399	12.010964	524.954621	381.000000
17.311980	11.607362	-1.765399	12.106528	527.607366	384.000000
17.339493	11.652174	-1.765399	12.201336	529.644295	387.000000
17.371239	11.624036	-1.765399	12.296522	528.365293	390.000000
17.400868	11.676144	-1.765399	18.000032	530.733816	393.000000
17.430497	11.742842	-1.765399	18.000032	533.765525	396.000000
17.460126	11.740757	-1.765399	18.000032	533.670784	399.000000
17.489756	11.711577	-1.765773	18.000032	532.344411	402.000000
17.523618	11.724083	-1.765773	18.000032	532.912857	405.000000
17.549014	11.769937	-1.765399	18.000032	534.997157	408.000000
17.580760	11.792865	-1.765399	18.000032	536.039307	411.000000
17.612505	11.838719	-1.765399	18.000032	538.123606	414.000000
17.637902	11.803286	-1.765773	18.000032	536.513011	417.000000
17.671764	11.858520	-1.765399	18.000032	539.023645	420.000000
17.699276	11.886658	-1.765399	18.000032	540.302647	423.000000
17.731022	11.910628	-1.765399	18.000032	541.392168	426.000000
17.760651	11.840804	-1.765399	18.000032	538.218347	429.000000
17.794513	11.924176	-1.765399	18.000032	542.007984	432.000000
17.819910	11.954398	-1.765773	18.000032	543.381727	435.000000
17.851655	11.990873	-1.765773	18.000032	545.039693	438.000000
17.879168	12.003379	-1.765399	18.000032	545.608138	441.000000
17.910914	11.997126	-1.765399	18.000032	545.323915	444.000000
17.940543	12.041939	-1.765586	18.000032	547.360845	447.000000
17.968056	12.069034	-1.765773	18.000032	548.592477	450.000000
17.999801	12.086751	-1.765399	18.000032	549.397774	453.000000
18.031547	11.981494	-1.765399	18.000032	544.613358	456.000000
18.059060	12.094046	-1.765399	18.000032	549.729367	459.000000
18.090805	12.100299	-1.765399	18.000032	550.013590	462.000000
18.120434	12.135732	-1.765773	18.000032	551.624185	465.000000
18.150064	12.125311	-1.765960	18.000032	551.150481	468.000000
18.181809	12.173249	-1.765960	18.000032	553.329522	471.000000
18.211438	12.204514	-1.765773	18.000032	554.750635	474.000000
18.238951	12.243074	-1.765960	18.000032	556.503342	477.000000
18.270697	12.254537	-1.765399	18.000032	557.024417	480.000000
18.298210	12.140943	-1.765773	18.000032	551.861038	483.000000
18.329955	12.258706	-1.765773	18.000032	557.213899	486.000000
18.361701	12.253495	-1.765960	18.000032	556.977047	489.000000
18.391330	12.291012	-1.765773	18.000032	558.682383	492.000000
18.418843	12.268085	-1.765960	18.000032	557.640233	495.000000
18.448472	12.307687	-1.765399	18.000032	559.440310	498.000000
18.480217	12.320193	-1.765960	18.000032	560.008756	501.000000
18.509847	12.441082	-1.765773	18.000032	565.503728	504.000000
18.539476	12.325403	-1.765399	18.000032	560.245608	507.000000
18.569105	12.304560	-1.765960	18.000032	559.298199	510.000000
18.598734	12.412944	-1.765399	18.000032	564.224726	513.000000
18.632596	12.410860	-1.765773	18.000032	564.129985	516.000000
18.660109	12.449419	-1.765773	18.000032	565.882692	519.000000
18.687622	12.424408	-1.765960	18.000032	564.745801	522.000000
18.719367	12.460883	-1.765960	18.000032	566.403767	525.000000
18.751113	12.459841	-1.765399	18.000032	566.356396	528.000000
18.780742	12.541128	-1.765399	18.000032	570.051292	531.000000
18.806139	12.445251	-1.765773	18.000032	565.693210	534.000000
18.837884	12.448377	-1.765960	18.000032	565.835321	537.000000
18.869630	12.520285	-1.765773	18.000032	569.103883	540.000000
18.899259	12.558845	-1.765399	18.000032	570.856589	543.000000
18.928888	12.582814	-1.765399	18.000032	571.946110	546.000000
18.960634	12.568224	-1.765399	18.000032	571.282923	549.000000
18.992379	12.607826	-1.765773	18.000032	573.083001	552.000000
19.019892	12.607826	-1.765399	18.000032	573.083001	555.000000
19.049521	12.741221	-1.766147	18.000032	579.146419	558.000000
19.077034	12.580730	-1.765773	18.000032	571.851369	561.000000
19.115129	12.624500	-1.766147	18.000032	573.840928	564.000000
19.140525	12.635964	-1.765960	18.000032	574.362003	567.000000
19.170154	12.669313	-1.765399	18.000032	575.877857	570.000000
19.199784	12.652638	-1.765773	18.000032	575.119930	573.000000
19.229413	12.699535	-1.765399	18.000032	577.251600	576.000000
19.259042	12.717252	-1.765399	18.000032	578.056898	579.000000
19.290788	12.748516	-1.765399	18.000032	579.478012	582.000000
19.318300	12.708915	-1.765399	18.000032	577.677935	585.000000
19.347930	12.712041	-1.765773	18.000032	577.820046	588.000000
19.379675	12.771444	-1.765399	18.000032	580.520162	591.000000
19.409304	12.771444	-1.765960	18.000032	580.520162	594.000000
19.438934	12.807919	-1.765399	18.000032	582.178128	597.000000
19.470679	12.774570	-1.765960	18.000032	580.662273	600.000000
19.500308	12.824593	-1.765773	18.000032	582.936055	603.000000
19.527821	12.824593	-1.765960	18.000032	582.936055	606.000000
19.559567	12.851689	-1.765399	18.000032	584.167687	609.000000
19.589196	12.669313	-1.765399	18.000032	575.877857	612.000000
19.618825	12.830846	-1.765773	18.000032	583.220277	615.000000
19.650571	12.885038	-1.765399	18.000032	585.683541	618.000000
19.680200	12.897544	-1.765399	18.000032	586.251986	621.000000
19.709829	12.929850	-1.765399	18.000032	587.720471	624.000000
19.739458	12.882954	-1.766147	18.000032	585.588800	627.000000
19.769088	12.929850	-1.765399	18.000032	587.720471	630.000000
19.798717	12.937145	-1.765773	18.000032	588.052064	633.000000
19.830462	12.966326	-1.765773	18.000032	589.378436	636.000000
19.860092	12.803750	-1.765960	18.000032	581.988646	639.000000
19.889721	12.964241	-1.765773	18.000032	589.283695	642.000000
19.919350	12.970494	-1.765399	18.000032	589.567918	645.000000
19.948979	13.004885	-1.765399	18.000032	591.131143	648.000000
19.978608	12.999674	-1.765960	18.000032	590.894291	651.000000
20.010354	13.028855	-1.765773	18.000032	592.220664	654.000000
20.039983	13.051782	-1.765399	18.000032	593.262813	657.000000
20.067496	13.063246	-1.765960	18.000032	593.783888	660.000000
20.101358	13.082004	-1.765399	18.000032	594.636557	663.000000
20.130987	12.895459	-1.765773	18.000032	586.157246	666.000000
20.160616	13.078878	-1.765960	18.000032	594.494445	669.000000
20.190245	13.071583	-1.765399	18.000032	594.162852	672.000000
20.219875	13.099721	-1.765773	18.000032	595.441854	675.000000
20.249504	13.076793	-1.765399	18.000032	594.399704	678.000000
20.279133	13.125775	-1.765399	18.000032	596.626116	681.000000
20.308762	13.133070	-1.765399	18.000032	596.957709	684.000000
20.338391	13.174756	-1.765399	18.000032	598.852527	687.000000
20.370137	13.151828	-1.765399	18.000032	597.810377	690.000000
20.393417	13.014264	-1.765399	18.000032	591.557477	693.000000
20.427279	13.186219	-1.765399	18.000032	599.373602	696.000000
20.461141	13.184135	-1.765960	18.000032	599.278861	699.000000
20.488654	13.206020	-1.765960	18.000032	600.273640	702.000000
20.516167	13.162250	-1.765399	18.000032	598.284081	705.000000
20.550029	13.224779	-1.765399	18.000032	601.126309	708.000000
20.579658	13.214357	-1.765399	18.000032	600.652604	711.000000
20.609287	13.258128	-1.765399	18.000032	602.642163	714.000000
20.638916	13.195599	-1.765399	18.000032	599.799936	717.000000
20.672778	13.060119	-1.765960	18.000032	593.641777	720.000000
20.698175	13.274802	-1.765773	18.000032	603.400090	723.000000
20.727804	13.288350	-1.765399	18.000032	604.015906	726.000000
20.759549	13.314404	-1.765960	18.000032	605.200168	729.000000
20.787062	13.294603	-1.765773	18.000032	604.300129	732.000000
20.820924	13.324825	-1.765399	18.000032	605.673872	735.000000
20.850553	13.312319	-1.765960	18.000032	605.105427	738.000000
20.878066	13.360258	-1.765773	18.000032	607.284467	741.000000
20.909812	13.283139	-1.765960	18.000032	603.779054	744.000000
20.935208	13.224779	-1.765960	18.000032	601.126309	747.000000
20.969070	13.337331	-1.765399	18.000032	606.242318	750.000000
20.998699	13.375891	-1.765960	18.000032	607.995024	753.000000
21.028328	13.349837	-1.765399	18.000032	606.810763	756.000000
21.057958	13.391523	-1.765960	18.000032	608.705581	759.000000
21.087587	13.424872	-1.765773	18.000032	610.221436	762.000000
21.119332	13.417577	-1.765399	18.000032	609.889842	765.000000
21.148962	13.447799	-1.765399	18.000032	611.263586	768.000000
21.180707	13.374848	-1.765399	18.000032	607.947654	771.000000
21.214569	13.347752	-1.765960	18.000032	606.716022	774.000000
21.239966	13.429040	-1.765399	18.000032	610.410917	777.000000
21.267478	13.451967	-1.766147	18.000032	611.453067	780.000000
21.299224	13.426956	-1.765773	18.000032	610.316176	783.000000
21.328853	13.463431	-1.765960	18.000032	611.974142	786.000000
21.358482	13.471768	-1.765399	18.000032	612.353106	789.000000
21.388112	13.500949	-1.765960	18.000032	613.679479	792.000000
21.417741	13.441546	-1.765773	18.000032	610.979363	795.000000
21.445254	13.470726	-1.765960	18.000032	612.305735	798.000000
21.474883	13.441546	-1.765399	18.000032	610.979363	801.000000
21.508745	13.518665	-1.765960	18.000032	614.484776	804.000000
21.538374	13.545761	-1.765399	18.000032	615.716408	807.000000
21.570119	13.512412	-1.765773	18.000032	614.200554	810.000000
21.599749	13.537424	-1.765399	18.000032	615.337444	813.000000
21.629378	13.558267	-1.765399	18.000032	616.284854	816.000000
21.659007	13.568688	-1.765773	18.000032	616.758558	819.000000
21.684404	13.493653	-1.765773	18.000032	613.347885	822.000000
21.718265	13.567646	-1.765399	18.000032	616.711188	825.000000
21.739429	13.363385	-1.765399	18.000032	607.426579	828.000000
21.777524	13.608290	-1.765399	18.000032	618.558635	831.000000
21.807153	13.615585	-1.765960	18.000032	618.890228	834.000000
21.841015	13.609332	-1.765773	18.000032	618.606006	837.000000
21.868528	13.634344	-1.765399	18.000032	619.742897	840.000000
21.896041	13.646850	-1.765773	18.000032	620.311342	843.000000
21.927786	13.660397	-1.765960	18.000032	620.927158	846.000000
21.959532	13.578068	-1.765773	18.000032	617.184892	849.000000
21.987045	13.654145	-1.765399	18.000032	620.642935	852.000000
22.027256	13.635386	-1.765773	18.000032	619.790267	855.000000
22.046303	13.671861	-1.765399	18.000032	621.448233	858.000000
22.078049	13.653102	-1.765586	18.000032	620.595565	861.000000
22.107678	13.692704	-1.765773	18.000032	622.395642	864.000000
22.137307	13.708336	-1.765773	18.000032	623.106199	867.000000
22.169053	13.741685	-1.765773	18.000032	624.622053	870.000000
22.198682	13.734390	-1.765399	18.000032	624.290460	873.000000
22.224078	13.643723	-1.765960	18.000032	620.169231	876.000000
22.257940	13.731264	-1.765399	18.000032	624.148349	879.000000
22.289686	13.677072	-1.765399	18.000032	621.685085	882.000000
22.317199	13.753149	-1.765773	18.000032	625.143128	885.000000
22.346828	13.725011	-1.765960	18.000032	623.864126	888.000000
22.376457	13.759402	-1.765773	18.000032	625.427351	891.000000
22.408203	13.758360	-1.765960	18.000032	625.379980	894.000000
22.435715	13.796919	-1.765399	18.000032	627.132687	897.000000
22.467461	13.741685	-1.765773	18.000032	624.622053	900.000000
22.501323	13.748980	-1.765773	18.000032	624.953646	903.000000
22.528836	13.812551	-1.766147	18.000032	627.843244	906.000000
22.558465	13.806298	-1.765399	18.000032	627.559021	909.000000
22.588094	13.836521	-1.765399	18.000032	628.932764	912.000000
22.617723	13.802130	-1.765399	18.000032	627.369539	915.000000
22.647352	13.841732	-1.765399	18.000032	629.169617	918.000000
22.676982	13.827141	-1.765960	18.000032	628.506430	921.000000
22.706611	13.881333	-1.765586	18.000032	630.969694	924.000000
22.738356	13.795877	-1.765399	18.000032	627.085317	927.000000
22.765869	13.800046	-1.765399	18.000032	627.274799	930.000000
22.797615	13.852153	-1.765960	18.000032	629.643321	933.000000
22.825128	13.781287	-1.765399	18.000032	626.422130	936.000000
22.856873	13.883418	-1.765960	18.000032	631.064435	939.000000
22.888619	13.891755	-1.765773	18.000032	631.443398	942.000000
22.918248	13.918851	-1.765773	18.000032	632.675030	945.000000
22.945761	13.908429	-1.765960	18.000032	632.201326	948.000000
22.977506	13.970958	-1.765399	18.000032	635.043553	951.000000
23.009252	13.864659	-1.765399	18.000032	630.211767	954.000000
23.036765	13.905303	-1.765773	18.000032	632.059214	957.000000
23.066394	13.916766	-1.765399	18.000032	632.580289	960.000000
23.098140	13.939694	-1.766147	18.000032	633.622439	963.000000
23.127769	13.914682	-1.765773	18.000032	632.485548	966.000000
23.159514	13.954284	-1.765399	18.000032	634.285626	969.000000
23.187027	13.964705	-1.765399	18.000032	634.759330	972.000000
23.218773	13.983464	-1.766147	18.000032	635.611998	975.000000
23.246286	13.950115	-1.766147	18.000032	634.096144	978.000000
23.280147	13.944904	-1.765399	18.000032	633.859292	981.000000
23.305544	13.992843	-1.766147	18.000032	636.038332	984.000000
23.337290	13.987633	-1.765399	18.000032	635.801480	987.000000
23.369035	14.012644	-1.765773	18.000032	636.938371	990.000000
23.394432	13.992843	-1.765399	18.000032	636.038332	993.000000
23.426177	14.008476	-1.766147	18.000032	636.748889	996.000000
23.457923	14.014728	-1.765773	18.000032	637.033112	999.000000
23.487552	14.039740	-1.765399	18.000032	638.170003	1002.000000
23.517181	13.936567	-1.765399	18.000032	633.480328	1005.000000
23.551043	14.028276	-1.765399	18.000032	637.648928	1008.000000
23.576439	14.054330	-1.765773	18.000032	638.833189	1011.000000
23.606069	14.072047	-1.765773	18.000032	639.638487	1014.000000
23.635698	14.081426	-1.765399	18.000032	640.064821	1017.000000
23.667443	14.062667	-1.765399	18.000032	639.212153	1020.000000
23.699189	14.093932	-1.765960	18.000032	640.633266	1023.000000
23.728818	14.084553	-1.765960	18.000032	640.206932	1026.000000
23.758447	14.098100	-1.765773	18.000032	640.822748	1029.000000
23.783844	14.000138	-1.765773	18.000032	636.369926	1032.000000
23.817706	14.098100	-1.765399	18.000032	640.822748	1035.000000
23.847335	14.094974	-1.765773	18.000032	640.680637	1038.000000
23.876964	14.119986	-1.766147	18.000032	641.817528	1041.000000
23.906593	14.083510	-1.765773	18.000032	640.159562	1044.000000
23.936223	14.146039	-1.765773	18.000032	643.001789	1047.000000
23.967968	14.150208	-1.765399	18.000032	643.191271	1050.000000
23.997597	14.158545	-1.766147	18.000032	643.570234	1053.000000
24.025110	14.176262	-1.765399	18.000032	644.375532	1056.000000
24.058972	14.058499	-1.765960	18.000032	639.022671	1059.000000
24.086485	14.168967	-1.765960	18.000032	644.043939	1062.000000
24.118231	14.153334	-1.765773	18.000032	643.333382	1065.000000
24.145743	14.179388	-1.765399	18.000032	644.517643	1068.000000
24.177489	14.150208	-1.765773	18.000032	643.191271	1071.000000
24.207118	14.192936	-1.765399	18.000032	645.133459	1074.000000
24.236747	14.193978	-1.765399	18.000032	645.180830	1077.000000
24.266377	14.225243	-1.765399	18.000032	646.601943	1080.000000
24.296006	14.191894	-1.765773	18.000032	645.086089	1083.000000
24.329868	14.134576	-1.765399	18.000032	642.480714	1086.000000
24.357380	14.232538	-1.765399	18.000032	646.933536	1089.000000
24.387010	14.229411	-1.765960	18.000032	646.791425	1092.000000
24.416639	14.247128	-1.765773	18.000032	647.596723	1095.000000
24.448384	14.216906	-1.765399	18.000032	646.222980	1098.000000
24.478014	14.259634	-1.765960	18.000032	648.165168	1101.000000
24.507643	14.237749	-1.766147	18.000032	647.170389	1104.000000
24.537272	14.273182	-1.765773	18.000032	648.780984	1107.000000
24.566901	14.212737	-1.765960	18.000032	646.033498	1110.000000
24.592298	14.183557	-1.765960	18.000032	644.707125	1113.000000
24.626160	14.269013	-1.765773	18.000032	648.591502	1116.000000
24.657905	14.294025	-1.766147	18.000032	649.728393	1119.000000
24.685418	14.311741	-1.765960	18.000032	650.533691	1122.000000
24.719280	14.285687	-1.765399	18.000032	649.349430	1125.000000
24.746793	14.316952	-1.765960	18.000032	650.770543	1128.000000
24.774306	14.308615	-1.766147	18.000032	650.391580	1131.000000
24.808168	14.338837	-1.765773	18.000032	651.765323	1134.000000
24.833564	14.258592	-1.765399	18.000032	648.117798	1137.000000
24.865310	14.279435	-1.765399	18.000032	649.065207	1140.000000
24.897055	14.314868	-1.765960	18.000032	650.675802	1143.000000
24.924568	14.341964	-1.765773	18.000032	651.907434	1146.000000
24.956314	14.317994	-1.765773	18.000032	650.817914	1149.000000
24.985943	14.353427	-1.765399	18.000032	652.428509	1152.000000
25.017688	14.391987	-1.766147	18.000032	654.181216	1155.000000
25.047318	14.375312	-1.765773	18.000032	653.423288	1158.000000
25.076947	14.405535	-1.765399	18.000032	654.797032	1161.000000
25.104460	14.315910	-1.765773	18.000032	650.723173	1164.000000
25.136205	14.358638	-1.765399	18.000032	652.665361	1167.000000
25.167951	14.379481	-1.765399	18.000032	653.612770	1170.000000
25.197580	14.391987	-1.765960	18.000032	654.181216	1173.000000
25.222976	14.361764	-1.765960	18.000032	652.807473	1176.000000
25.256838	14.404493	-1.765773	18.000032	654.749661	1179.000000
25.286467	14.408661	-1.765399	18.000032	654.939143	1182.000000
25.316097	14.429504	-1.765960	18.000032	655.886552	1185.000000
25.345726	14.375312	-1.765960	18.000032	653.423288	1188.000000
25.375355	14.386776	-1.765399	18.000032	653.944363	1191.000000
25.404984	14.435757	-1.765399	18.000032	656.170775	1194.000000
25.436730	14.442010	-1.765773	18.000032	656.454997	1197.000000
25.466359	14.459726	-1.765399	18.000032	657.260295	1200.000000
25.498105	14.425336	-1.765773	18.000032	655.697070	1203.000000
25.523501	14.458684	-1.765399	18.000032	657.212925	1206.000000
25.555247	14.480569	-1.765773	18.000032	658.207704	1209.000000
25.584876	14.475359	-1.765399	18.000032	657.970852	1212.000000
25.616621	14.399282	-1.766147	18.000032	654.512809	1215.000000
25.644134	14.462853	-1.765399	18.000032	657.402407	1218.000000
25.675880	14.473274	-1.765399	18.000032	657.876111	1221.000000
25.705509	14.498286	-1.765773	18.000032	659.013002	1224.000000
25.735138	14.512876	-1.765399	18.000032	659.676188	1227.000000
25.769000	14.500370	-1.766147	18.000032	659.107743	1230.000000
25.796513	14.518087	-1.765960	18.000032	659.913041	1233.000000
25.826142	14.533719	-1.765399	18.000032	660.623597	1236.000000
25.857888	14.536846	-1.765773	18.000032	660.765709	1239.000000
25.887517	14.448263	-1.765399	18.000032	656.739220	1242.000000
25.915030	14.527466	-1.766147	18.000032	660.339375	1245.000000
25.946775	14.517045	-1.765960	18.000032	659.865670	1248.000000
25.974288	14.552478	-1.766147	18.000032	661.476265	1251.000000
26.006034	14.512876	-1.765399	18.000032	659.676188	1254.000000
26.035663	14.558731	-1.765773	18.000032	661.760488	1257.000000
26.065292	14.558731	-1.765399	18.000032	661.760488	1260.000000
26.097038	14.655651	-1.765399	18.000032	666.165940	1263.000000
26.124550	14.567068	-1.765960	18.000032	662.139452	1266.000000
26.154180	14.483696	-1.765399	18.000032	658.349816	1269.000000
26.185925	14.579574	-1.765399	18.000032	662.707897	1272.000000
26.217671	14.575405	-1.765773	18.000032	662.518415	1275.000000
26.247300	14.598332	-1.765960	18.000032	663.560565	1278.000000
26.274813	14.569152	-1.765773	18.000032	662.234193	1281.000000
26.304442	14.594164	-1.765960	18.000032	663.371084	1284.000000
26.336188	14.593122	-1.765960	18.000032	663.323713	1287.000000
26.365817	14.637934	-1.766147	18.000032	665.360643	1290.000000
26.395446	14.572279	-1.765773	18.000032	662.376304	1293.000000
26.422959	14.548309	-1.765960	18.000032	661.286784	1296.000000
26.454704	14.638976	-1.765773	18.000032	665.408013	1299.000000
26.486450	14.642103	-1.765399	18.000032	665.550124	1302.000000
26.516079	14.658777	-1.765960	18.000032	666.308052	1305.000000
26.547825	14.631681	-1.765773	18.000032	665.076420	1308.000000
26.577454	14.659819	-1.765399	18.000032	666.355422	1311.000000
26.607083	14.643145	-1.765960	18.000032	665.597495	1314.000000
26.634596	14.729643	-1.765960	18.000032	669.529242	1317.000000
26.666342	14.600417	-1.765399	18.000032	663.655306	1320.000000
26.695971	14.644187	-1.765773	18.000032	665.644865	1323.000000
26.725600	14.665030	-1.765960	18.000032	666.592274	1326.000000
26.755229	14.684831	-1.765399	18.000032	667.492313	1329.000000
26.784858	14.672325	-1.765773	18.000032	666.923868	1332.000000
26.814488	14.692126	-1.765773	18.000032	667.823906	1335.000000
26.846233	14.717138	-1.765773	18.000032	668.960797	1338.000000
26.873746	14.701505	-1.765399	18.000032	668.250240	1341.000000
26.905491	14.758824	-1.765773	18.000032	670.855615	1344.000000
26.937237	14.658777	-1.765399	18.000032	666.308052	1347.000000
26.971099	14.692126	-1.765399	18.000032	667.823906	1350.000000
26.996495	14.712969	-1.765399	18.000032	668.771315	1353.000000
27.026125	14.727559	-1.766147	18.000032	669.434502	1356.000000
27.055754	14.698379	-1.765399	18.000032	668.108129	1359.000000
27.085383	14.732770	-1.765399	18.000032	669.671354	1362.000000
27.115012	14.734854	-1.765399	18.000032	669.766095	1365.000000
27.144641	14.759866	-1.766147	18.000032	670.902986	1368.000000
27.174271	14.675452	-1.765399	18.000032	667.065979	1371.000000
27.203900	14.700463	-1.765960	18.000032	668.202870	1374.000000
27.235645	14.768203	-1.765960	18.000032	671.281949	1377.000000
27.263158	14.758824	-1.765960	18.000032	670.855615	1380.000000
27.294904	14.783835	-1.765960	18.000032	671.992506	1383.000000
27.326649	14.758824	-1.765399	18.000032	670.855615	1386.000000
27.354162	14.776540	-1.765399	18.000032	671.660913	1389.000000
27.385908	14.782793	-1.765399	18.000032	671.945136	1392.000000
27.415537	14.800510	-1.765399	18.000032	672.750433	1395.000000
27.445166	14.679620	-1.765773	18.000032	667.255461	1398.000000
27.474795	14.779667	-1.766147	18.000032	671.803024	1401.000000
27.504425	14.815100	-1.765960	18.000032	673.413620	1404.000000
27.534054	14.825521	-1.765773	18.000032	673.887324	1407.000000
27.567916	14.836985	-1.765773	18.000032	674.408399	1410.000000
27.597545	14.817184	-1.765773	18.000032	673.508360	1413.000000
27.622941	14.834900	-1.765399	18.000032	674.313658	1416.000000
27.656803	14.833858	-1.765960	18.000032	674.266288	1419.000000
27.684316	14.846364	-1.765960	18.000032	674.834733	1422.000000
27.716062	14.692126	-1.765025	18.000032	667.823906	1425.000000
27.745691	14.833858	-1.765960	18.000032	674.266288	1428.000000
27.773204	14.831774	-1.765773	18.000032	674.171547	1431.000000
27.804949	14.855743	-1.765960	18.000032	675.261067	1434.000000
27.834578	14.838027	-1.765960	18.000032	674.455770	1437.000000
27.868440	14.879713	-1.765773	18.000032	676.350588	1440.000000
27.895953	14.892219	-1.765399	18.000032	676.919033	1443.000000
27.925582	14.888050	-1.765399	18.000032	676.729551	1446.000000
27.953095	14.897429	-1.766147	18.000032	677.155885	1449.000000
27.986957	14.765076	-1.765399	18.000032	671.139838	1452.000000
28.014470	14.897429	-1.765960	18.000032	677.155885	1455.000000
28.041983	14.883882	-1.765773	18.000032	676.540069	1458.000000
28.073728	14.902640	-1.765960	18.000032	677.392738	1461.000000
28.103358	14.868249	-1.765399	18.000032	675.829513	1464.000000
28.135103	14.908893	-1.765773	18.000032	677.676960	1467.000000
28.164732	14.897429	-1.765399	18.000032	677.155885	1470.000000
28.194362	14.933905	-1.765773	18.000032	678.813851	1473.000000
28.223991	14.889092	-1.765773	18.000032	676.776922	1476.000000
28.257853	14.722348	-1.765399	18.000032	669.197649	1479.000000
28.285366	14.946411	-1.765399	18.000032	679.382297	1482.000000
28.317111	14.944326	-1.765773	18.000032	679.287556	1485.000000
28.346740	14.958916	-1.765773	18.000032	679.950742	1488.000000
28.376370	14.930778	-1.766147	18.000032	678.671740	1491.000000
28.405999	14.958916	-1.765773	18.000032	679.950742	1494.000000
28.435628	14.945368	-1.766147	18.000032	679.334926	1497.000000
28.463141	14.973506	-1.765399	18.000032	680.613928	1500.000000
28.494886	14.454516	-1.765773	18.000032	657.023443	2.500000
28.520283	14.918272	-1.765773	18.000032	678.103294	5.500000
28.554145	15.148588	-1.765399	18.000032	688.572164	8.500000
28.583774	15.175684	-1.765399	18.000032	689.803796	11.500000
28.615519	15.175684	-1.765773	18.000032	689.803796	14.500000
28.647265	15.135040	-1.765960	18.000032	687.956349	17.500000
28.674778	15.138166	-1.765399	18.000032	688.098460	20.500000
28.702291	15.116281	-1.766147	18.000032	687.103680	23.500000
28.734036	15.125660	-1.765960	18.000032	687.530014	26.500000
28.765782	15.025614	-1.765773	18.000032	682.982451	29.500000
28.799644	14.967254	-1.765773	18.000032	680.329706	32.500000
28.822924	15.060005	-1.765773	18.000032	684.545676	35.500000
28.852553	15.070426	-1.765773	18.000032	685.019380	38.500000
28.884299	15.038120	-1.765399	18.000032	683.550896	41.500000
28.916044	15.058963	-1.765399	18.000032	684.498306	44.500000
28.943557	15.075637	-1.765399	18.000032	685.256233	47.500000
28.973186	15.069384	-1.765773	18.000032	684.972010	50.500000
29.002815	15.075637	-1.765960	18.000032	685.256233	53.500000
29.032445	15.004771	-1.765773	18.000032	682.035042	56.500000
29.062074	14.983928	-1.765399	18.000032	681.087633	59.500000
29.093819	15.060005	-1.765773	18.000032	684.545676	62.500000
29.123449	15.065216	-1.766147	18.000032	684.782528	65.500000
29.150961	15.036035	-1.765399	18.000032	683.456156	68.500000
29.184823	15.067300	-1.765399	18.000032	684.877269	71.500000
29.212336	15.063131	-1.765960	18.000032	684.687787	74.500000
29.241965	15.079806	-1.765773	18.000032	685.445715	77.500000
29.273711	15.021445	-1.765773	18.000032	682.792969	80.500000
29.303340	15.045415	-1.765399	18.000032	683.882490	83.500000
29.326620	14.894303	-1.765960	18.000032	677.013774	86.500000
29.364715	15.095438	-1.765960	18.000032	686.156271	89.500000
29.394344	15.108986	-1.765773	18.000032	686.772087	92.500000
29.421857	15.065216	-1.765399	18.000032	684.782528	95.500000
29.453603	15.100649	-1.765399	18.000032	686.393124	98.500000
29.485348	15.104817	-1.765773	18.000032	686.582605	101.500000
29.512861	15.110028	-1.765960	18.000032	686.819458	104.500000
29.544606	15.017277	-1.765960	18.000032	682.603487	107.500000
29.574236	15.100649	-1.765399	18.000032	686.393124	110.500000
29.603865	15.075637	-1.765399	18.000032	685.256233	113.500000
29.633494	15.136082	-1.765399	18.000032	688.003719	116.500000
29.663123	15.127745	-1.765773	18.000032	687.624755	119.500000
29.694869	15.135040	-1.765399	18.000032	687.956349	122.500000
29.722382	15.151714	-1.765773	18.000032	688.714276	125.500000
29.756244	15.159009	-1.765960	18.000032	689.045869	128.500000
29.783756	15.160051	-1.765399	18.000032	689.093239	131.500000
29.815502	15.071469	-1.765399	18.000032	685.066751	134.500000
29.840898	15.152756	-1.765399	18.000032	688.761646	137.500000
29.870528	15.061047	-1.765773	18.000032	684.593046	140.500000
29.904390	15.171515	-1.766147	18.000032	689.614314	143.500000
29.934019	15.131913	-1.765399	18.000032	687.814237	146.500000
29.963648	15.164220	-1.765399	18.000032	689.282721	149.500000
29.993277	15.173599	-1.765399	18.000032	689.709055	152.500000
30.025023	15.205906	-1.765399	18.000032	691.177539	155.500000
30.052536	15.173599	-1.765399	18.000032	689.709055	158.500000
30.082165	15.104817	-1.765773	18.000032	686.582605	161.500000
30.113910	15.200695	-1.765399	18.000032	690.940687	164.500000
30.145656	15.192358	-1.765773	18.000032	690.561723	167.500000
30.173169	15.211117	-1.765399	18.000032	691.414392	170.500000
30.204914	15.175684	-1.765399	18.000032	689.803796	173.500000
30.232427	15.209032	-1.766147	18.000032	691.319651	176.500000
30.264173	15.201737	-1.765586	18.000032	690.988058	179.500000
30.293802	15.238213	-1.765773	18.000032	692.646023	182.500000
30.323431	15.160051	-1.765773	18.000032	689.093239	185.500000
30.350944	15.152756	-1.765773	18.000032	688.761646	188.500000
30.382689	15.234044	-1.765960	18.000032	692.456542	191.500000
30.425017	15.108986	-1.765399	18.000032	686.772087	194.500000
30.444064	15.265308	-1.765399	18.000032	693.877655	197.500000
30.473693	15.217370	-1.765773	18.000032	691.698614	200.500000
30.503323	15.250718	-1.765960	18.000032	693.214469	203.500000
30.532952	15.238213	-1.765773	18.000032	692.646023	206.500000
30.562581	15.280941	-1.765399	18.000032	694.588212	209.500000
30.594327	15.192358	-1.765773	18.000032	690.561723	212.500000
30.621839	15.213201	-1.765399	18.000032	691.509133	215.500000
30.651469	15.248634	-1.765399	18.000032	693.119728	218.500000
30.683214	15.265308	-1.765773	18.000032	693.877655	221.500000
30.712843	15.259056	-1.765399	18.000032	693.593432	224.500000
30.742473	15.272603	-1.766147	18.000032	694.209248	227.500000
30.772102	15.296573	-1.765399	18.000032	695.298769	230.500000
30.803847	15.284067	-1.765399	18.000032	694.730323	233.500000
30.831360	15.325753	-1.765773	18.000032	696.625141	236.500000
30.860989	15.217370	-1.765773	18.000032	691.698614	239.500000
30.894851	15.275730	-1.765773	18.000032	694.351360	242.500000
30.924481	15.284067	-1.765773	18.000032	694.730323	245.500000
30.951993	15.296573	-1.765399	18.000032	695.298769	248.500000
30.983739	15.260098	-1.765773	18.000032	693.640803	251.500000
31.013368	15.298657	-1.765586	18.000032	695.393510	254.500000
31.042997	15.303868	-1.765399	18.000032	695.630362	257.500000
31.072627	15.321585	-1.765399	18.000032	696.435660	260.500000
31.102256	15.245508	-1.765399	18.000032	692.977617	263.500000
31.131885	15.294489	-1.765773	18.000032	695.204028	266.500000
31.161514	15.330964	-1.765960	18.000032	696.861994	269.500000
31.193260	15.327837	-1.766147	18.000032	696.719882	272.500000
31.222889	15.336175	-1.766147	18.000032	697.098846	275.500000
31.254634	15.289278	-1.765960	18.000032	694.967176	278.500000
31.282147	15.338259	-1.765399	18.000032	697.193587	281.500000
31.313893	15.334090	-1.765399	18.000032	697.004105	284.500000
31.341406	15.345554	-1.765399	18.000032	697.525180	287.500000
31.373151	15.242381	-1.765399	18.000032	692.835505	290.500000
31.407013	15.334090	-1.765399	18.000032	697.004105	293.500000
31.432410	15.344512	-1.765399	18.000032	697.477810	296.500000
31.464155	15.360144	-1.766147	18.000032	698.188366	299.500000
31.491668	15.366397	-1.765399	18.000032	698.472589	302.500000
31.521297	15.370566	-1.765399	18.000032	698.662071	305.500000
31.550926	15.379945	-1.765399	18.000032	699.088405	308.500000
31.582672	15.367439	-1.765773	18.000032	698.519960	311.500000
31.612301	15.387240	-1.765773	18.000032	699.419998	314.500000
31.644047	15.288236	-1.765399	18.000032	694.919805	317.500000
31.671560	15.365355	-1.765773	18.000032	698.425219	320.500000
31.703305	15.364313	-1.765399	18.000032	698.377848	323.500000
31.732934	15.392451	-1.765773	18.000032	699.656850	326.500000
31.762564	15.354933	-1.765773	18.000032	697.951514	329.500000
31.792193	15.398704	-1.765399	18.000032	699.941073	332.500000
31.821822	15.392451	-1.765399	18.000032	699.656850	335.500000
31.853568	15.417462	-1.765773	18.000032	700.793741	338.500000
31.881080	15.417462	-1.765399	18.000032	700.793741	341.500000
31.914942	15.313247	-1.765773	18.000032	696.056696	344.500000
31.942455	15.411209	-1.765399	18.000032	700.509519	347.500000
31.972084	15.396619	-1.765399	18.000032	699.846332	350.500000
32.001714	15.409125	-1.765960	18.000032	700.414778	353.500000
32.031343	15.379945	-1.766147	18.000032	699.088405	356.500000
32.063088	15.432052	-1.766147	18.000032	701.456928	359.500000
32.092717	15.409125	-1.765960	18.000032	700.414778	362.500000
32.122347	15.435179	-1.766147	18.000032	701.599039	365.500000
32.151976	15.379945	-1.765960	18.000032	699.088405	368.500000
32.185838	15.367439	-1.765399	18.000032	698.519960	371.500000
32.211234	15.440390	-1.765960	18.000032	701.835891	374.500000
32.240863	15.438305	-1.765399	18.000032	701.741150	377.500000
32.272609	15.443516	-1.765773	18.000032	701.978003	380.500000
32.304355	15.417462	-1.765960	18.000032	700.793741	383.500000
32.331867	15.444558	-1.765399	18.000032	702.025373	386.500000
32.363613	15.429968	-1.765773	18.000032	701.362187	389.500000
32.393242	15.469570	-1.765773	18.000032	703.162264	392.500000
32.422871	15.370566	-1.765773	18.000032	698.662071	395.500000
32.456733	15.378903	-1.765399	18.000032	699.041035	398.500000
32.482130	15.439347	-1.765773	18.000032	701.788521	401.500000
32.511759	15.459148	-1.765773	18.000032	702.688559	404.500000
32.541388	15.459148	-1.766147	18.000032	702.688559	407.500000
32.571017	15.451853	-1.765960	18.000032	702.356966	410.500000
32.602763	15.518551	-1.765399	18.000032	705.388675	413.500000
32.632392	15.471654	-1.765399	18.000032	703.257005	416.500000
32.662021	15.498750	-1.765212	18.000032	704.488637	419.500000
32.693767	15.425800	-1.765773	18.000032	701.172705	422.500000
32.719163	15.427884	-1.766147	18.000032	701.267446	425.500000
32.748793	15.464359	-1.765399	18.000032	702.925412	428.500000
32.780538	15.478949	-1.765399	18.000032	703.588598	431.500000
32.812284	15.453938	-1.765399	18.000032	702.451707	434.500000
32.841913	15.479991	-1.765773	18.000032	703.635968	437.500000
32.871542	15.496666	-1.765773	18.000032	704.393896	440.500000
32.903288	15.500834	-1.765399	18.000032	704.583377	443.500000
32.930801	15.484160	-1.765399	18.000032	703.825450	446.500000
32.964662	15.450811	-1.765960	18.000032	702.309596	449.500000
32.990059	15.463317	-1.765773	18.000032	702.878041	452.500000
33.021804	15.492497	-1.765773	18.000032	704.204414	455.500000
33.053550	15.503961	-1.765960	18.000032	704.725489	458.500000
33.078947	15.471654	-1.765399	18.000032	703.257005	461.500000
33.112808	15.500834	-1.765960	18.000032	704.583377	464.500000
33.142438	15.513340	-1.765773	18.000032	705.151823	467.500000
33.172067	15.513340	-1.765960	18.000032	705.151823	470.500000
33.201696	15.415378	-1.765960	18.000032	700.699000	473.500000
33.231325	15.484160	-1.765960	18.000032	703.825450	476.500000
33.260954	15.512298	-1.765773	18.000032	705.104452	479.500000
33.290584	15.525846	-1.765399	18.000032	705.720268	482.500000
33.324446	15.535225	-1.765960	18.000032	706.146602	485.500000
33.354075	15.495624	-1.765960	18.000032	704.346525	488.500000
33.381588	15.525846	-1.765773	18.000032	705.720268	491.500000
33.413333	15.534183	-1.765399	18.000032	706.099232	494.500000
33.440846	15.534183	-1.765960	18.000032	706.099232	497.500000
33.472592	15.450811	-1.765773	18.000032	702.309596	500.500000
33.500104	15.518551	-1.765960	18.000032	705.388675	503.500000
33.531850	15.513340	-1.765960	18.000032	705.151823	506.500000
33.561479	15.532099	-1.765960	18.000032	706.004491	509.500000
33.591108	15.525846	-1.765399	18.000032	705.720268	512.500000
33.620738	15.536267	-1.765773	18.000032	706.193973	515.500000
33.650367	15.553984	-1.765399	18.000032	706.999271	518.500000
33.682112	15.584206	-1.765960	18.000032	708.373014	521.500000
33.711742	15.560237	-1.765399	18.000032	707.283493	524.500000
33.743487	15.481033	-1.765960	18.000032	703.683339	527.500000
33.773116	15.542520	-1.765960	18.000032	706.478196	530.500000
33.800629	15.525846	-1.765399	18.000032	705.720268	533.500000
33.832375	15.550858	-1.765773	18.000032	706.857159	536.500000
33.859888	15.516467	-1.766147	18.000032	705.293934	539.500000
33.891633	15.547731	-1.765399	18.000032	706.715048	542.500000
33.921262	15.542520	-1.765399	18.000032	706.478196	545.500000
33.950891	15.580038	-1.765960	18.000032	708.183532	548.500000
33.980521	15.538352	-1.765399	18.000032	706.288714	551.500000
34.014383	15.477907	-1.765773	18.000032	703.541228	554.500000
34.039779	15.561279	-1.765399	18.000032	707.330864	557.500000
34.073641	15.559195	-1.765399	18.000032	707.236123	560.500000
34.101154	15.562321	-1.765773	18.000032	707.378234	563.500000
34.132899	15.531057	-1.765399	18.000032	705.957121	566.500000
34.160412	15.563363	-1.765773	18.000032	707.425605	569.500000
34.192158	15.544605	-1.765025	18.000032	706.572937	572.500000
34.221787	15.613387	-1.765773	18.000032	709.699386	575.500000
34.251416	15.511256	-1.765960	18.000032	705.057082	578.500000
34.278929	15.528972	-1.765399	18.000032	705.862380	581.500000
34.312791	15.567532	-1.765960	18.000032	707.615086	584.500000
34.340304	15.572743	-1.765399	18.000032	707.851939	587.500000
34.372049	15.576911	-1.765960	18.000032	708.041421	590.500000
34.399562	15.546689	-1.765773	18.000032	706.667677	593.500000
34.429191	15.575869	-1.765960	18.000032	707.994050	596.500000
34.460937	15.555026	-1.765960	18.000032	707.046641	599.500000
34.490566	15.605049	-1.765399	18.000032	709.320423	602.500000
34.522312	15.525846	-1.765960	18.000032	705.720268	605.500000
34.556174	15.522719	-1.765773	18.000032	705.578157	608.500000
34.581570	15.547731	-1.765773	18.000032	706.715048	611.500000
34.611199	15.562321	-1.765773	18.000032	707.378234	614.500000
34.640829	15.540436	-1.765399	18.000032	706.383455	617.500000
34.670458	15.564405	-1.765399	18.000032	707.472975	620.500000
34.700087	15.580038	-1.765399	18.000032	708.183532	623.500000
34.729716	15.568574	-1.765399	18.000032	707.662457	626.500000
34.759345	15.479991	-1.765773	18.000032	703.635968	629.500000
34.786858	15.514382	-1.765773	18.000032	705.199193	632.500000
34.818604	15.552942	-1.765773	18.000032	706.951900	635.500000
34.850349	15.550858	-1.765399	18.000032	706.857159	638.500000
34.879978	15.561279	-1.765399	18.000032	707.330864	641.500000
34.911724	15.532099	-1.765399	18.000032	706.004491	644.500000
34.941353	15.555026	-1.765773	18.000032	707.046641	647.500000
34.970982	15.548773	-1.765960	18.000032	706.762418	650.500000
35.000612	15.559195	-1.765773	18.000032	707.236123	653.500000
35.030241	15.437263	-1.765399	18.000032	701.693780	656.500000
35.059870	15.526888	-1.765773	18.000032	705.767639	659.500000
35.089499	15.545647	-1.765399	18.000032	706.620307	662.500000
35.123361	15.544605	-1.765960	18.000032	706.572937	665.500000
35.150874	15.546689	-1.765773	18.000032	706.667677	668.500000
35.182620	15.526888	-1.765399	18.000032	705.767639	671.500000
35.208016	15.527930	-1.765399	18.000032	705.815009	674.500000
35.241878	15.517509	-1.765773	18.000032	705.341305	677.500000
35.269391	15.518551	-1.765399	18.000032	705.388675	680.500000
35.301136	15.362228	-1.765399	18.000032	698.283107	683.500000
35.330766	15.496666	-1.765960	18.000032	704.393896	686.500000
35.360395	15.481033	-1.765399	18.000032	703.683339	689.500000
35.390024	15.493539	-1.765399	18.000032	704.251784	692.500000
35.421770	15.477907	-1.765399	18.000032	703.541228	695.500000
35.449282	15.459148	-1.765399	18.000032	702.688559	698.500000
35.481028	15.463317	-1.765773	18.000032	702.878041	701.500000
35.510657	15.451853	-1.765773	18.000032	702.356966	704.500000
35.540286	15.434137	-1.765399	18.000032	701.551669	707.500000
35.563566	15.278856	-1.765773	18.000032	694.493471	710.500000
35.601661	15.395577	-1.765960	18.000032	699.798962	713.500000
35.629174	15.364313	-1.765773	18.000032	698.377848	716.500000
35.658803	15.362228	-1.765960	18.000032	698.283107	719.500000
35.690549	15.315332	-1.765399	18.000032	696.151437	722.500000
35.720178	15.334090	-1.766147	18.000032	697.004105	725.500000
35.749807	15.309079	-1.765399	18.000032	695.867214	728.500000
35.779436	15.296573	-1.765399	18.000032	695.298769	731.500000
35.809065	15.248634	-1.765773	18.000032	693.119728	734.500000
35.842927	15.081890	-1.765399	18.000032	685.540455	737.500000
35.870440	15.197569	-1.765399	18.000032	690.798576	740.500000
35.900069	15.155883	-1.765399	18.000032	688.903758	743.500000
35.931815	15.137124	-1.765773	18.000032	688.051089	746.500000
35.957211	15.071469	-1.765399	-3.087370	685.066751	749.500000
35.988957	15.068342	-1.765212	-2.923438	684.924640	752.500000
36.020703	15.014150	-1.765399	-2.767439	682.461376	755.500000
36.050332	14.998518	-1.765399	-2.629192	681.750819	758.500000
36.079961	14.879713	-1.765960	-2.494723	676.350588	761.500000
36.113823	14.785919	-1.765773	-2.363653	672.087247	764.500000
36.141336	14.852617	-1.765399	-2.242098	675.118956	767.500000
36.170965	14.792172	-1.765399	-2.106118	672.371470	770.500000
36.200594	14.750486	-1.765773	-1.989402	670.476651	773.500000
36.230223	14.662946	-1.766147	-1.876085	666.497533	776.500000
36.257736	14.642103	-1.765773	-1.758991	665.550124	779.500000
36.289482	14.554562	-1.766147	-1.627921	661.571006	782.500000
36.321227	14.527466	-1.765773	-1.499873	660.339375	785.500000
36.346624	14.371144	-1.765773	-1.375980	653.233807	788.500000
36.374137	14.238791	-1.765399	-1.261530	647.217759	791.500000
36.410115	14.258592	-1.765399	-1.142358	648.117798	794.500000
36.439744	14.221074	-1.765399	-1.041313	646.412461	797.500000
36.469373	14.128323	-1.765960	-0.943294	642.196491	800.500000
36.499002	14.048077	-1.765960	-0.860761	638.548966	803.500000
36.528632	14.001181	-1.765773	-0.758587	636.417296	806.500000
36.560377	13.891755	-1.765773	-0.670295	631.443398	809.500000
36.590006	13.829226	-1.765399	-0.608631	628.601171	812.500000
36.621752	13.645807	-1.765399	-0.508490	620.263972	815.500000
36.655614	13.524918	-1.765399	-0.368166	614.768999	818.500000
36.681010	13.478021	-1.765773	-0.231714	612.637329	821.500000
36.710640	13.393607	-1.765773	-0.086338	608.800322	824.500000
36.740269	13.248748	-1.765399	0.048840	602.215829	827.500000
36.769898	13.163292	-1.765399	0.161590	598.331452	830.500000
36.799527	13.076793	-1.765399	0.257815	594.399704	833.500000
36.831273	12.951736	-1.765960	0.287136	588.715250	836.500000
36.858786	12.786034	-1.765773	0.302953	581.183348	839.500000
36.892648	12.628669	-1.765399	0.286333	574.030410	842.500000
36.909579	12.407733	-1.765399	0.351963	563.987874	845.500000
36.947673	12.382722	-1.765773	0.437422	562.850983	848.500000
36.979419	12.268085	-1.765960	0.490351	557.640233	851.500000
37.011164	12.074245	-1.765773	0.545262	548.829329	854.500000
37.040794	11.949187	-1.765399	0.632894	543.144874	857.500000
37.070423	11.801202	-1.765960	0.696446	536.418270	860.500000
37.100052	11.640711	-1.765399	0.727513	529.123220	863.500000
37.129681	11.387468	-1.766147	0.673121	517.612200	866.500000
37.157194	-0.051586	-1.765960	-18.000032	-2.344837	869.500000
37.188940	-0.060445	-1.765399	-18.000032	-2.747486	872.500000
37.214336	-0.059924	-1.765399	-18.000032	-2.723801	875.000000