File: Code/Example GUIs/Stress-Strain analyzer/SS_Data/C250/C250-3d1.txt
*
POSN mm 	LOAD kn	STRAIN1 %	STRAIN2 %	STRESS(MPA)	TIME(sec)
-13.442344	0.004690	-1.771197	0.001496	0.213167	0.000000
-13.431762	0.091188	-1.771384	0.002251	4.144915	1.000000
-13.421180	0.174560	-1.771384	0.001024	7.934551	2.000000
-13.410598	0.335051	-1.771384	0.001779	15.229601	3.000000
-13.401075	0.619558	-1.771384	0.006406	28.161734	4.000000
-13.391551	0.908755	-1.771197	0.010797	41.307035	5.000000
-13.380969	1.219315	-1.771197	0.016274	55.423430	6.000000
-13.371445	1.555409	-1.771384	0.022459	70.700401	7.000000
-13.364038	1.790414	-1.771384	0.027039	81.382438	8.000000
-13.352398	2.165067	-1.771384	0.033697	98.412116	9.000000
-13.340758	2.506371	-1.771197	0.040307	113.925939	10.000000
-13.332293	2.825269	-1.771384	0.046162	128.421297	11.000000
-13.321711	3.140519	-1.771384	0.052016	142.750859	12.000000
-13.311129	3.459417	-1.771010	0.058815	157.246218	13.000000
-13.300547	3.758514	-1.771384	0.065142	170.841538	14.000000
-13.292081	4.043021	-1.771197	0.070336	183.773672	15.000000
-13.281500	4.358792	-1.771384	0.076899	198.126919	16.000000
-13.270918	4.652679	-1.771010	0.082989	211.485386	17.000000
-13.262452	4.960113	-1.771010	0.089127	225.459670	18.000000
-13.251870	5.237846	-1.771384	0.094652	238.083896	19.000000
-13.241289	5.482230	-1.771010	0.099704	249.192267	20.000000
-13.230707	5.786017	-1.771384	0.105936	263.000754	21.000000
-13.221183	6.042907	-1.771010	0.111602	274.677570	22.000000
-13.211659	6.276348	-1.771197	0.115851	285.288552	23.000000
-13.201077	6.519169	-1.771197	0.121423	296.325867	24.000000
-13.190496	6.729162	-1.771384	0.125767	305.871014	25.000000
-13.182030	7.016275	-1.771010	0.131244	318.921573	26.000000
-13.171448	7.234084	-1.771010	0.135493	328.821998	27.000000
-13.160866	7.451893	-1.771384	0.139648	338.722423	28.000000
-13.151343	7.683772	-1.771384	0.143944	349.262348	29.000000
-13.139703	7.877090	-1.771571	0.148430	358.049567	30.000000
-13.131237	8.076662	-1.771010	0.152066	367.121009	31.000000
-13.122772	8.331468	-1.771384	0.156929	378.703085	32.000000
-13.112190	8.541982	-1.771384	0.161131	388.271916	33.000000
-13.101608	8.750933	-1.771010	0.165994	397.769692	34.000000
-13.088910	8.904650	-1.771384	0.168733	404.756834	35.000000
-13.082561	9.170399	-1.771384	0.174493	416.836299	36.000000
-13.071979	9.384039	-1.771384	0.178081	426.547242	37.000000
-13.061397	9.628423	-1.771384	0.183369	437.655613	38.000000
-13.051873	9.843106	-1.771384	0.187902	447.413926	39.000000
-13.041291	10.085823	-1.771384	0.193001	458.446505	40.000000
-13.031768	10.303632	-1.771010	0.197015	468.346930	41.000000
-13.021186	10.448491	-1.771010	0.200036	474.931422	42.000000
-13.010604	10.753841	-1.771197	0.206033	488.810965	43.000000
-13.000022	10.982072	-1.771197	0.211132	499.185094	44.000000
-12.991557	11.203008	-1.771197	0.216231	509.227630	45.000000
-12.982033	11.437492	-1.771010	0.221000	519.885982	46.000000
-12.972509	11.643837	-1.771197	0.225485	529.265332	47.000000
-12.961928	11.861647	-1.771384	0.230585	539.165756	48.000000
-12.953462	12.132606	-1.771010	0.235306	551.482074	49.000000
-12.940764	12.346246	-1.771197	0.240311	561.193017	50.000000
-12.931240	12.591152	-1.771384	0.245505	572.325073	51.000000
-12.919600	12.782907	-1.771384	0.249660	581.041237	52.000000
-12.913251	13.018433	-1.771384	0.254381	591.746959	53.000000
-12.902669	13.249790	-1.771010	0.258914	602.263200	54.000000
-12.892087	13.505117	-1.771384	0.264485	613.868960	55.000000
-12.881505	13.717716	-1.771384	0.268735	623.532533	56.000000
-12.871982	13.945947	-1.771197	0.273362	633.906662	57.000000
-12.862458	14.167925	-1.771384	0.278367	643.996568	58.000000
-12.851876	14.336753	-1.771197	0.282333	651.670582	59.000000
-12.841294	14.618133	-1.771384	0.288423	664.460604	60.000000
-12.832829	14.825521	-1.771384	0.293098	673.887324	61.000000
-12.818014	15.001644	-1.771384	0.297583	681.892931	62.000000
-12.811665	15.240297	-1.771010	0.301974	692.740764	63.000000
-12.803200	15.415378	-1.771384	0.305846	700.699000	64.000000
-12.791560	15.667578	-1.771384	0.311795	712.162650	65.000000
-12.782036	15.867671	-1.771197	0.316139	721.257777	66.000000
-12.771454	16.051089	-1.771384	0.319869	729.594977	67.000000
-12.761930	16.259519	-1.771197	0.324260	739.069067	68.000000
-12.750290	16.397083	-1.771010	0.327282	745.321967	69.000000
-12.741825	16.613850	-1.771010	0.331909	755.175021	70.000000
-12.731243	16.826449	-1.771758	0.336536	764.838593	71.000000
-12.721719	16.998404	-1.771010	0.340691	772.654718	72.000000
-12.712196	17.182864	-1.771197	0.344751	781.039288	73.000000
-12.702672	17.349608	-1.771197	0.348529	788.618561	74.000000
-12.691032	17.495509	-1.771197	0.351928	795.250424	75.000000
-12.682567	17.627862	-1.771384	0.355422	801.266472	76.000000
-12.671985	17.854009	-1.771197	0.360427	811.545860	77.000000
-12.662461	17.993657	-1.771010	0.363637	817.893501	78.000000
-12.651879	18.160401	-1.771384	0.367367	825.472773	79.000000
-12.642355	18.300049	-1.771384	0.371097	831.820414	80.000000
-12.632832	18.400095	-1.771384	0.373836	836.367977	81.000000
-12.621192	18.582472	-1.771384	0.377566	844.657806	82.000000
-12.610610	18.712740	-1.771384	0.381485	850.579113	83.000000
-12.601086	18.835714	-1.771384	0.384790	856.168826	84.000000
-12.591563	18.933676	-1.771010	0.387387	860.621649	85.000000
-12.583097	19.000374	-1.771384	0.388378	863.653358	86.000000
-12.572515	19.155654	-1.771197	0.392392	870.711555	87.000000
-12.561933	19.253616	-1.771197	0.394752	875.164378	88.000000
-12.551352	19.322398	-1.771384	0.396499	878.290828	89.000000
-12.542886	19.419318	-1.771384	0.398860	882.696280	90.000000
-12.532304	19.486016	-1.771197	0.400938	885.727989	91.000000
-12.521722	19.571472	-1.771384	0.403251	889.612366	92.000000
-12.512199	19.691319	-1.771197	0.405848	895.059968	93.000000
-12.501617	19.781986	-1.771384	0.408492	899.181197	94.000000
-12.492093	19.873696	-1.771384	0.410475	903.349797	95.000000
-12.479395	19.944562	-1.771384	0.412694	906.570988	96.000000
-12.471988	20.046088	-1.771384	0.415338	911.185818	97.000000
-12.462464	20.137797	-1.771197	0.418124	915.354418	98.000000
-12.451882	20.233675	-1.771384	0.420768	919.712500	99.000000
-12.441300	20.317047	-1.771197	0.422185	923.502136	100.000000
-12.430718	20.412925	-1.771384	0.425206	927.860218	101.000000
-12.420136	20.498381	-1.771384	0.427425	931.744595	102.000000
-12.411671	20.444189	-1.771384	0.426906	929.281331	103.000000
-12.402147	20.708895	-1.771384	0.433044	941.313426	104.000000
-12.391565	20.842291	-1.771197	0.436821	947.376844	105.000000
-12.382042	20.952758	-1.771384	0.439937	952.398112	106.000000
-12.371460	21.100744	-1.771384	0.443998	959.124717	107.000000
-12.361936	21.217465	-1.771384	0.447397	964.430207	108.000000
-12.352413	21.380040	-1.771197	0.451175	971.819998	109.000000
-12.341831	21.542615	-1.771384	0.456463	979.209789	110.000000
-12.332307	21.667673	-1.771384	0.459910	984.894243	111.000000
-12.321725	21.819827	-1.771197	0.465670	991.810329	112.000000
-12.312202	21.930295	-1.771384	0.468928	996.831597	113.000000
-12.301620	22.067859	-1.771010	0.473744	1003.084497	114.000000
-12.292096	22.242940	-1.771384	0.479126	1011.042733	115.000000
-12.282572	22.382588	-1.771197	0.483564	1017.390374	116.000000
-12.271990	22.493056	-1.771384	0.488097	1022.411642	117.000000
-12.262467	22.651463	-1.771384	0.493102	1029.611950	118.000000
-12.251885	22.784858	-1.771384	0.497776	1035.675368	119.000000
-12.242361	22.878652	-1.771384	0.501978	1039.938709	120.000000
-12.231779	23.064154	-1.771384	0.508305	1048.370650	121.000000
-12.222256	23.197549	-1.771197	0.513593	1054.434068	122.000000
-12.211674	23.343450	-1.771384	0.519354	1061.065931	123.000000
-12.202150	23.476846	-1.771384	0.524925	1067.129349	124.000000
-12.191568	23.576892	-1.771384	0.529741	1071.676912	125.000000
-12.180987	23.764479	-1.771384	0.536493	1080.203594	126.000000
-12.172521	23.904127	-1.771197	0.542489	1086.551235	127.000000
-12.161939	24.022932	-1.771197	0.548438	1091.951466	128.000000
-12.152415	24.177170	-1.771384	0.555237	1098.962293	129.000000
-12.140775	24.202182	-1.771384	0.559015	1100.099184	130.000000
-12.132310	24.452298	-1.771010	0.568269	1111.468093	131.000000
-12.122786	24.594030	-1.771384	0.575446	1117.910474	132.000000
-12.112204	24.725341	-1.771384	0.582245	1123.879151	133.000000
-12.101623	24.869158	-1.771384	0.589988	1130.416274	134.000000
-12.092099	24.981710	-1.772693	0.596881	1135.532283	135.000000
-12.082575	25.094262	-1.772132	0.604200	1140.648292	136.000000
-12.073052	25.235995	-1.772132	0.611282	1147.090673	137.000000
-12.061412	25.369390	-1.772132	0.619828	1153.154091	138.000000
-12.051888	25.477774	-1.772132	0.627382	1158.080618	139.000000
-12.043422	25.604916	-1.771945	0.635881	1163.859814	140.000000
-12.032841	25.727890	-1.772132	0.643861	1169.449527	141.000000
-12.022259	25.819599	-1.771945	0.651651	1173.618127	142.000000
-12.011677	25.961331	-1.772319	0.660622	1180.060508	143.000000
-12.002153	26.061378	-1.772132	0.668365	1184.608072	144.000000
-11.992629	26.182267	-1.772132	0.677808	1190.103044	145.000000
-11.982048	26.278145	-1.772132	0.686543	1194.461126	146.000000
-11.971466	26.334421	-1.772319	0.695184	1197.019130	147.000000
-11.961942	26.490743	-1.772132	0.706799	1204.124698	148.000000
-11.952418	26.584537	-1.771384	0.716242	1208.388039	149.000000
-11.941837	26.667909	-1.771945	0.726535	1212.177675	150.000000
-11.932313	26.784630	-1.772132	0.737300	1217.483166	151.000000
-11.923847	26.861749	-1.771945	0.748065	1220.988580	152.000000
-11.912207	26.947205	-1.772132	0.758735	1224.872957	153.000000
-11.901626	27.070179	-1.772132	0.770162	1230.462670	154.000000
-11.892102	27.136876	-1.771758	0.781729	1233.494379	155.000000
-11.882578	27.224417	-1.771945	0.793297	1237.473497	156.000000
-11.869880	27.136876	-1.771758	0.799860	1233.494379	157.000000
-11.861414	27.378655	-1.771384	0.815394	1244.484324	158.000000
-11.851891	27.472449	-1.771945	0.829370	1248.747665	159.000000
-11.842367	27.539146	-1.772132	0.842495	1251.779374	160.000000
-11.832843	27.607928	-1.771945	0.856896	1254.905824	161.000000
-11.823320	27.689216	-1.772132	0.872052	1258.600719	162.000000
-11.812738	27.749661	-1.774003	0.887633	1261.348205	163.000000
-11.802156	27.728818	-1.773628	0.900948	1260.400796	164.000000
-11.792632	27.878887	-1.774003	0.919189	1267.222142	165.000000
-11.780992	27.939332	-1.774003	0.935809	1269.969628	166.000000
-11.771469	27.997692	-1.774003	0.952523	1272.622373	167.000000
-11.761945	28.045631	-1.773816	0.969238	1274.801414	168.000000
-11.752421	28.072727	-1.773816	0.986329	1276.033046	169.000000
-11.742898	28.137340	-1.774003	1.005404	1278.970014	170.000000
-11.732316	28.206122	-1.773816	1.023724	1282.096464	171.000000
-11.723850	28.233218	-1.774003	1.044215	1283.328095	172.000000
-11.712210	28.287410	-1.774003	1.066029	1285.791359	173.000000
-11.700570	28.283241	-1.773628	1.088126	1285.601877	174.000000
-11.692105	28.341602	-1.773628	1.110978	1288.254623	175.000000
-11.682581	28.391625	-1.773628	1.135530	1290.528404	176.000000
-11.671999	28.420805	-1.773628	1.159515	1291.854777	177.000000
-11.662476	28.445817	-1.774190	1.183123	1292.991668	178.000000
-11.652952	28.466660	-1.773816	1.208903	1293.939077	179.000000
-11.643428	28.483334	-1.773628	1.234493	1294.697004	180.000000
-11.632846	28.479165	-1.773816	1.260556	1294.507522	181.000000
-11.622265	28.531273	-1.773628	1.290019	1296.876045	182.000000
-11.611683	28.539610	-1.774003	1.319198	1297.255009	183.000000
-11.598984	28.487503	-1.774003	1.348188	1294.886486	184.000000
-11.592635	28.587549	-1.774003	1.378878	1299.434049	185.000000
-11.582053	28.539610	-1.773628	1.409757	1297.255009	186.000000
-11.572530	28.600055	-1.773816	1.443468	1300.002495	187.000000
-11.563006	28.608392	-1.773628	1.475480	1300.381458	188.000000
-11.553482	28.587549	-1.773628	1.509192	1299.434049	189.000000
-11.541842	28.600055	-1.773816	1.543659	1300.002495	190.000000
-11.531261	28.537526	-1.773628	1.576332	1297.160268	191.000000
-11.522795	28.612561	-1.773628	1.612216	1300.570940	192.000000
-11.512213	28.593802	-1.774003	1.648477	1299.718272	193.000000
-11.502690	28.591718	-1.774003	1.685117	1299.623531	194.000000
-11.492108	28.606308	-1.773816	1.722322	1300.286718	195.000000
-11.482584	28.581296	-1.774003	1.760567	1299.149827	196.000000
-11.472002	28.564622	-1.773816	1.798245	1298.391899	197.000000
-11.462478	28.600055	-1.773816	1.833791	1300.002495	198.000000
-11.452955	28.579212	-1.773628	1.873830	1299.055086	199.000000
-11.442373	28.560453	-1.774003	1.912735	1298.202418	200.000000
-11.431791	28.541694	-1.773628	1.952963	1297.349749	201.000000
-11.423326	28.541694	-1.773628	1.992057	1297.349749	202.000000
-11.412744	28.495840	-1.774003	2.030585	1295.265450	203.000000
-11.403220	28.531273	-1.774003	2.072134	1296.876045	204.000000
-11.392638	28.525020	-1.773628	2.110284	1296.591822	205.000000
-11.382056	28.516683	-1.774003	2.151834	1296.212859	206.000000
-11.370416	28.491671	-1.774003	2.192061	1295.075968	207.000000
-11.361951	28.422889	-1.773441	2.232289	1291.949518	208.000000
-11.351369	28.479165	-1.774190	2.275727	1294.507522	209.000000
-11.342904	28.466660	-1.774003	2.316710	1293.939077	210.000000
-11.335496	28.364529	-1.773628	2.355048	1289.296773	211.000000
-11.322798	28.462491	-1.773816	2.393198	1293.749595	212.000000
-11.311158	28.408299	-1.773628	2.436637	1291.286332	213.000000
-11.302692	28.406215	-1.774003	2.479886	1291.191591	214.000000
-11.292111	28.399962	-1.774003	2.523135	1290.907368	215.000000
-11.282587	28.379119	-1.773441	2.567706	1289.959959	216.000000
-11.273063	28.370782	-1.774190	2.610767	1289.580995	217.000000
-11.263540	28.312421	-1.773628	2.653827	1286.928250	218.000000
-11.252958	28.322843	-1.773816	2.696699	1287.401954	219.000000
-11.243434	28.287410	-1.773628	2.739381	1285.791359	220.000000
-11.232852	28.316590	-1.774003	2.784897	1287.117732	221.000000
-11.222270	28.279073	-1.773628	2.829657	1285.412395	222.000000
-11.211688	28.262398	-1.773816	2.875928	1284.654468	223.000000
-11.201107	28.237387	-1.773628	2.920499	1283.517577	224.000000
-11.192641	28.112329	-1.774003	2.958649	1277.833123	225.000000
-11.183117	28.214459	-1.773628	3.005487	1282.475427	226.000000
-11.173594	28.195701	-1.773816	3.049492	1281.622759	227.000000
-11.161954	28.183195	-1.773628	3.094252	1281.054314	228.000000
-11.152430	28.149846	-1.774003	3.138445	1279.538459	229.000000
-11.143965	28.087317	-1.773816	3.181128	1276.696232	230.000000
-11.133383	28.112329	-1.773816	3.225699	1277.833123	231.000000
-11.122801	28.103992	-1.774003	3.267627	1277.454159	232.000000
-11.113277	28.070643	-1.773628	3.312765	1275.938305	233.000000
-11.102695	28.058137	-1.774003	3.357525	1275.369859	234.000000
-11.091055	27.985186	-1.774190	3.401340	1272.053928	235.000000
-11.082590	27.985186	-1.773628	3.444023	1272.053928	236.000000
-11.074124	27.987271	-1.773628	3.488217	1272.148669	237.000000
-11.063542	27.945585	-1.774003	3.532221	1270.253850	238.000000
-11.052961	27.970596	-1.773628	3.572071	1271.390741	239.000000
-11.042379	27.912236	-1.774190	3.617020	1268.737996	240.000000
-11.031797	27.878887	-1.773816	3.659072	1267.222142	241.000000
-11.023331	27.858044	-1.774190	3.700999	1266.274732	242.000000
-11.012750	27.853876	-1.773816	3.745571	1266.085251	243.000000
-11.002168	27.820527	-1.774003	3.790142	1264.569396	244.000000
-10.992644	27.785094	-1.773816	3.833580	1262.958801	245.000000
-10.983120	27.783009	-1.773628	3.876640	1262.864060	246.000000
-10.972539	27.703806	-1.773628	3.918945	1259.263905	247.000000
-10.963015	27.728818	-1.773628	3.963894	1260.400796	248.000000
-10.953491	27.712143	-1.773628	4.006199	1259.642869	249.000000
-10.942909	27.668373	-1.773816	4.050015	1257.653310	250.000000
-10.932327	27.645446	-1.773628	4.093076	1256.611160	251.000000
-10.921746	27.512050	-1.773628	4.130848	1250.547742	252.000000
-10.913280	27.599591	-1.773816	4.173908	1254.526860	253.000000
-10.903756	27.582917	-1.773628	4.217724	1253.768933	254.000000
-10.893175	27.545399	-1.773628	4.261540	1252.063597	255.000000
-10.883651	27.541231	-1.773816	4.305356	1251.874115	256.000000
-10.873069	27.480786	-1.774003	4.348416	1249.126629	257.000000
-10.862487	27.445353	-1.774003	4.391476	1247.516033	258.000000
-10.854022	27.455774	-1.774003	4.433781	1247.989738	259.000000
-10.843440	27.424510	-1.774190	4.477597	1246.568624	260.000000
-10.832858	27.395330	-1.773628	4.520280	1245.242251	261.000000
-10.824393	27.353644	-1.773441	4.563718	1243.347433	262.000000
-10.813811	27.322379	-1.773628	4.606778	1241.926320	263.000000
-10.803229	27.270272	-1.773628	4.648328	1239.557797	264.000000
-10.794763	27.199405	-1.773628	4.689877	1236.336606	265.000000
-10.783123	27.345306	-1.773628	4.725383	1242.968470	266.000000
-10.772541	27.261934	-1.773628	4.774487	1239.178833	267.000000
-10.761960	27.205658	-1.774003	4.819814	1236.620829	268.000000
-10.752436	27.111865	-1.773628	4.863252	1232.357488	269.000000
-10.741854	27.151466	-1.774003	4.909712	1234.157565	270.000000
-10.733389	27.120202	-1.773628	4.952772	1232.736452	271.000000
-10.722807	27.078516	-1.773816	4.997721	1230.841634	272.000000
-10.712225	27.078516	-1.774003	5.041160	1230.841634	273.000000
-10.703759	27.005565	-1.773816	5.084220	1227.525702	274.000000
-10.693178	26.997228	-1.774003	5.129169	1227.146738	275.000000
-10.682596	26.980554	-1.773816	5.172607	1226.388811	276.000000
-10.672014	26.936784	-1.774003	5.216423	1224.399252	277.000000
-10.662490	26.926362	-1.773628	5.259861	1223.925548	278.000000
-10.650850	26.811726	-1.773816	5.299900	1218.714798	279.000000
-10.642385	26.851327	-1.773628	5.343338	1220.514875	280.000000
-10.632861	26.845074	-1.773628	5.386776	1220.230652	281.000000
-10.622279	26.811726	-1.773628	5.432480	1218.714798	282.000000
-10.612755	26.765871	-1.774003	5.475163	1216.630498	283.000000
-10.602174	26.740859	-1.773816	5.520112	1215.493607	284.000000
-10.592650	26.711679	-1.773816	5.563172	1214.167234	285.000000
-10.583126	26.599127	-1.773628	5.603589	1209.051226	286.000000
-10.573603	26.661656	-1.773816	5.650804	1211.893453	287.000000
-10.563021	26.622054	-1.773816	5.694998	1210.093375	288.000000
-10.552439	26.597043	-1.773628	5.739191	1208.956485	289.000000
-10.542915	26.557441	-1.774003	5.781874	1207.156407	290.000000
-10.532333	26.492828	-1.774003	5.825312	1204.219439	291.000000
-10.522810	26.507418	-1.774003	5.869883	1204.882626	292.000000
-10.511170	26.515755	-1.774003	5.909166	1205.261589	293.000000
-10.502704	26.436552	-1.774003	5.954871	1201.661435	294.000000
-10.493180	26.407371	-1.773441	5.999065	1200.335062	295.000000
-10.483657	26.323999	-1.773628	6.041747	1196.545426	296.000000
-10.473075	26.323999	-1.773628	6.085563	1196.545426	297.000000
-10.463551	26.315662	-1.773628	6.129379	1196.166462	298.000000
-10.451911	26.290651	-1.773628	6.173572	1195.029571	299.000000
-10.443446	26.267723	-1.774003	6.216633	1193.987422	300.000000
-10.433922	26.219784	-1.774003	6.261960	1191.808381	301.000000
-10.422282	26.165593	-1.773816	6.306153	1189.345117	302.000000
-10.413817	26.163508	-1.774003	6.349213	1189.250376	303.000000
-10.403235	26.130159	-1.773628	6.394918	1187.734522	304.000000
-10.392653	26.078052	-1.773816	6.438734	1185.365999	305.000000
-10.384187	26.000933	-1.773628	6.481039	1181.860586	306.000000
-10.371489	26.044703	-1.773628	6.523344	1183.850145	307.000000
-10.363024	25.961331	-1.773628	6.567160	1180.060508	308.000000
-10.352442	25.967584	-1.773816	6.613242	1180.344731	309.000000
-10.341860	25.940488	-1.773816	6.657813	1179.113099	310.000000
-10.333394	25.911308	-1.773628	6.702384	1177.786727	311.000000
-10.323871	25.869622	-1.773628	6.746956	1175.891909	312.000000
-10.312231	25.761238	-1.773628	6.788505	1170.965381	313.000000
-10.303765	25.819599	-1.773441	6.834587	1173.618127	314.000000
-10.293183	25.773744	-1.774003	6.878403	1171.533827	315.000000
-10.282601	25.729974	-1.773628	6.923352	1169.544268	316.000000
-10.274136	25.711215	-1.773628	6.967546	1168.691600	317.000000
-10.263554	25.644518	-1.773441	7.012117	1165.659891	318.000000
-10.252972	25.611169	-1.774003	7.056688	1164.144036	319.000000
-10.244507	25.600747	-1.773628	7.090683	1163.670332	320.000000
-10.233925	25.602832	-1.773628	7.138276	1163.765073	321.000000
-10.223343	25.536134	-1.773628	7.184358	1160.733364	322.000000
-10.213819	25.490279	-1.774003	7.229685	1158.649064	323.000000
-10.204296	25.463184	-1.774190	7.274257	1157.417432	324.000000
-10.193714	25.423582	-1.774003	7.319583	1155.617355	325.000000
-10.183132	25.402739	-1.773441	7.365288	1154.669946	326.000000
-10.172550	25.369390	-1.773441	7.409104	1153.154091	327.000000
-10.163026	25.329788	-1.773628	7.455563	1151.354014	328.000000
-10.153503	25.286018	-1.773628	7.500890	1149.364455	329.000000
-10.142921	25.202646	-1.773628	7.543951	1145.574819	330.000000
-10.133397	25.229742	-1.773816	7.590788	1146.806451	331.000000
-10.122815	25.194309	-1.773628	7.636493	1145.195855	332.000000
-10.114350	25.117190	-1.773816	7.682197	1141.690442	333.000000
-10.102710	25.127611	-1.773816	7.723747	1142.164146	334.000000
-10.094244	25.052576	-1.774003	7.768696	1138.753474	335.000000
-10.083663	25.044239	-1.773628	7.814022	1138.374510	336.000000
-10.073081	25.010890	-1.773628	7.858971	1136.858655	337.000000
-10.063557	24.977542	-1.773628	7.903543	1135.342801	338.000000
-10.052975	24.950446	-1.773628	7.949625	1134.111169	339.000000
-10.041335	24.848315	-1.773628	7.993441	1129.468865	340.000000
-10.032870	24.846231	-1.773628	8.038012	1129.374124	341.000000
-10.023346	24.844146	-1.773816	8.084850	1129.279383	342.000000
-10.012764	24.794123	-1.773628	8.130932	1127.005601	343.000000
-10.002182	24.752437	-1.774190	8.175125	1125.110783	344.000000
-9.993717	24.712836	-1.773816	8.221585	1123.310706	345.000000
-9.984193	24.669065	-1.773628	8.266156	1121.321147	346.000000
-9.973611	24.533586	-1.773254	8.302418	1115.162988	347.000000
-9.964088	24.623211	-1.773628	8.353788	1119.236847	348.000000
-9.953506	24.560682	-1.773441	8.399870	1116.394620	349.000000
-9.941866	24.527333	-1.773628	8.446708	1114.878765	350.000000
-9.933400	24.493984	-1.773628	8.490524	1113.362911	351.000000
-9.922818	24.416865	-1.773628	8.535851	1109.857497	352.000000
-9.913295	24.412696	-1.774003	8.582688	1109.668016	353.000000
-9.903771	24.387685	-1.773628	8.625749	1108.531125	354.000000
-9.893189	24.331409	-1.774003	8.671831	1105.973120	355.000000
-9.882607	24.310566	-1.774003	8.718668	1105.025711	356.000000
-9.875200	24.200098	-1.773628	8.763240	1100.004443	357.000000
-9.863560	24.210519	-1.773816	8.810077	1100.478148	358.000000
-9.852978	24.170918	-1.773628	8.856537	1098.678071	359.000000
-9.843454	24.122979	-1.773628	8.902242	1096.499030	360.000000
-9.832873	24.122979	-1.773816	8.945302	1096.499030	361.000000
-9.823349	24.047944	-1.773628	8.991384	1093.088357	362.000000
-9.812767	23.993752	-1.773816	9.036711	1090.625094	363.000000
-9.803243	23.977078	-1.773628	9.082038	1089.867166	364.000000
-9.792662	23.952066	-1.773628	9.130764	1088.730275	365.000000
-9.784196	23.877031	-1.773816	9.175713	1085.319603	366.000000
-9.774672	23.822839	-1.773816	9.222550	1082.856339	367.000000
-9.764091	23.810334	-1.773628	9.267122	1082.287894	368.000000
-9.753509	23.722793	-1.773628	9.312448	1078.308776	369.000000
-9.742927	23.731130	-1.773816	9.360797	1078.687739	370.000000
-9.732345	23.687360	-1.773628	9.406501	1076.698180	371.000000
-9.722821	23.643590	-1.773816	9.453339	1074.708621	372.000000
-9.713298	23.585229	-1.773628	9.499044	1072.055876	373.000000
-9.702716	23.385136	-1.773628	9.530017	1062.960749	374.000000
-9.694250	23.547712	-1.773628	9.584031	1070.350540	375.000000
-9.682610	23.485183	-1.773628	9.633513	1067.508313	376.000000
-9.674145	23.414317	-1.773628	9.679595	1064.287122	377.000000
-9.663563	23.380968	-1.773816	9.725677	1062.771267	378.000000
-9.651923	23.312186	-1.773816	9.771382	1059.644817	379.000000
-9.643457	23.262163	-1.773816	9.817086	1057.371036	380.000000
-9.632876	23.276753	-1.774003	9.863924	1058.034222	381.000000
-9.623352	23.210055	-1.773628	9.912272	1055.002513	382.000000
-9.613828	23.145442	-1.773628	9.957599	1052.065545	383.000000
-9.604304	23.089166	-1.773816	10.004437	1049.507541	384.000000
-9.593723	23.059986	-1.774003	10.050141	1048.181168	385.000000
-9.583141	23.028721	-1.773254	10.099623	1046.760054	386.000000
-9.573617	22.993288	-1.774003	10.146460	1045.149459	387.000000
-9.563035	22.932843	-1.773628	10.188765	1042.401973	388.000000
-9.553512	22.884905	-1.773628	10.236358	1040.222932	389.000000
-9.543988	22.843219	-1.773628	10.284329	1038.328114	390.000000
-9.533406	22.730666	-1.773628	10.327767	1033.212105	391.000000
-9.523882	22.747341	-1.773816	10.378382	1033.970032	392.000000
-9.513301	22.709823	-1.774003	10.424464	1032.264696	393.000000
-9.503777	22.647294	-1.773816	10.473190	1029.422469	394.000000
-9.493195	22.601440	-1.773628	10.519650	1027.338169	395.000000
-9.484730	22.518068	-1.773628	10.566488	1023.548532	396.000000
-9.473089	22.509731	-1.773628	10.614837	1023.169569	397.000000
-9.463566	22.461792	-1.773628	10.662052	1020.990528	398.000000
-9.452984	22.393010	-1.773628	10.710778	1017.864078	399.000000
-9.443460	22.361745	-1.773628	10.759127	1016.442965	400.000000
-9.438169	22.197086	-1.773628	10.801054	1008.958433	401.000000
-9.423355	22.245024	-1.773628	10.852046	1011.137474	402.000000
-9.412773	22.209591	-1.773628	10.901150	1009.526878	403.000000
-9.404307	22.153315	-1.773816	10.950254	1006.968874	404.000000
-9.393726	22.101208	-1.773628	10.995581	1004.600351	405.000000
-9.381027	22.047016	-1.773628	11.046951	1002.137088	406.000000
-9.374678	21.976150	-1.773628	11.095300	998.915897	407.000000
-9.364096	21.921958	-1.773816	11.141382	996.452633	408.000000
-9.353515	21.888609	-1.773628	11.192375	994.936779	409.000000
-9.343991	21.828164	-1.774003	11.241856	992.189293	410.000000
-9.334467	21.786478	-1.773628	11.290205	990.294475	411.000000
-9.323885	21.742708	-1.773441	11.338931	988.304916	412.000000
-9.313303	21.642662	-1.773628	11.386146	983.757352	413.000000
-9.302722	21.623903	-1.773628	11.436761	982.904684	414.000000
-9.294256	21.603060	-1.773628	11.480577	981.957275	415.000000
-9.283674	21.515519	-1.773628	11.531947	977.978157	416.000000
-9.275209	21.459243	-1.773628	11.580674	975.420152	417.000000
-9.262511	21.375871	-1.773254	11.629022	971.630516	418.000000
-9.254045	21.352944	-1.773628	11.680015	970.588366	419.000000
-9.243463	21.300837	-1.773628	11.729496	968.219844	420.000000
-9.234998	21.223717	-1.774003	11.778600	964.714430	421.000000
-9.222299	21.196622	-1.773628	11.826571	963.482798	422.000000
-9.213834	21.111165	-1.773816	11.876431	959.598421	423.000000
-9.204310	21.046552	-1.773628	11.926290	956.661453	424.000000
-9.194787	21.031962	-1.773628	11.974638	955.998267	425.000000
-9.184205	20.961096	-1.773254	12.026764	952.777076	426.000000
-9.174681	20.883977	-1.773816	12.075868	949.271662	427.000000
-9.168332	20.729738	-1.773628	12.118551	942.260835	428.000000
-9.153517	20.798520	-1.773628	12.168788	945.387285	429.000000
-9.143994	20.692221	-1.773628	12.219780	940.555499	430.000000
-9.133412	20.660956	-1.773441	12.270773	939.134386	431.000000
-9.123888	20.600512	-1.773816	12.320632	936.386899	432.000000
-9.113306	20.548404	-1.773628	18.000032	934.018377	433.000000
-9.103783	20.475454	-1.773628	18.000032	930.702445	434.000000
-9.093201	20.342059	-1.773628	18.000032	924.639027	435.000000
-9.084735	20.375407	-1.773628	18.000032	926.154882	436.000000
-9.073095	20.308710	-1.773816	18.000032	923.123173	437.000000
-9.063572	20.225338	-1.773816	18.000032	919.333536	438.000000
-9.054048	20.166977	-1.773628	18.000032	916.680791	439.000000
-9.042408	20.071100	-1.773628	18.000032	912.322709	440.000000
-9.033942	20.016908	-1.773628	18.000032	909.859446	441.000000
-9.025477	20.008571	-1.773628	18.000032	909.480482	442.000000
-9.012779	19.914777	-1.773628	18.000032	905.217141	443.000000
-9.004313	19.854332	-1.774003	18.000032	902.469655	444.000000
-8.993731	19.756370	-1.773441	18.000032	898.016833	445.000000
-8.983150	19.700094	-1.773628	18.000032	895.458828	446.000000
-8.973626	19.658408	-1.773628	18.000032	893.564010	447.000000
-8.964102	19.581289	-1.773628	18.000032	890.058597	448.000000
-8.953520	19.512507	-1.773628	18.000032	886.932147	449.000000
-8.942938	19.445810	-1.773441	18.000032	883.900438	450.000000
-8.934473	19.366606	-1.773441	18.000032	880.300283	451.000000
-8.923891	19.258223	-1.774003	18.000032	875.373756	452.000000
-8.913309	19.241548	-1.773628	18.000032	874.615829	453.000000
-8.902727	19.162345	-1.773628	18.000032	871.015675	454.000000
-8.896378	19.041455	-1.773628	18.000032	865.520702	455.000000
-8.884738	19.051877	-1.773628	18.000032	865.994407	456.000000
-8.873098	18.922650	-1.774003	18.000032	860.120470	457.000000
-8.863575	18.891386	-1.773628	18.000032	858.699357	458.000000
-8.854051	18.828857	-1.773628	18.000032	855.857130	459.000000
-8.843469	18.718389	-1.773628	18.000032	850.835862	460.000000
-8.833945	18.657944	-1.773628	18.000032	848.088375	461.000000
-8.822305	18.524549	-1.773628	18.000032	842.024957	462.000000
-8.813840	18.489116	-1.773441	18.000032	840.414362	463.000000
-8.803258	18.441177	-1.774003	18.000032	838.235321	464.000000
-8.793734	18.355721	-1.773628	18.000032	834.350944	465.000000
-8.784211	18.278602	-1.773816	18.000032	830.845531	466.000000
-8.773629	18.195230	-1.773628	18.000032	827.055894	467.000000
-8.765163	18.107689	-1.773628	18.000032	823.076776	468.000000
-8.754581	17.999305	-1.773628	18.000032	818.150249	469.000000
-8.744000	17.961788	-1.773628	18.000032	816.444913	470.000000
-8.734476	17.874247	-1.773441	18.000032	812.465795	471.000000
-8.724952	17.799213	-1.773441	18.000032	809.055122	472.000000
-8.714370	17.717925	-1.773816	18.000032	805.360227	473.000000
-8.703789	17.594951	-1.773254	18.000032	799.770514	474.000000
-8.694265	17.549097	-1.773628	18.000032	797.686214	475.000000
-8.682625	17.490736	-1.774003	18.000032	795.033468	476.000000
-8.674159	17.365678	-1.773441	18.000032	789.349014	477.000000
-8.663577	17.292728	-1.773628	18.000032	786.033082	478.000000
-8.655112	17.148911	-1.773816	18.000032	779.495960	479.000000
-8.644530	17.109309	-1.773441	18.000032	777.695883	480.000000
-8.635006	17.040528	-1.773628	18.000032	774.569433	481.000000
-8.627599	16.840435	-1.773628	18.000032	765.474306	482.000000
-8.613843	16.934228	-1.773628	18.000032	769.737646	483.000000
-8.604319	16.742473	-1.773441	18.000032	761.021483	484.000000
-8.593737	16.657016	-1.774003	18.000032	757.137106	485.000000
-8.583155	16.615330	-1.773441	18.000032	755.242288	486.000000
-8.572574	16.490272	-1.773254	18.000032	749.557834	487.000000
-8.564108	16.392310	-1.773628	18.000032	745.105011	488.000000
-8.555643	16.273505	-1.773816	18.000032	739.704779	489.000000
-8.542944	16.202639	-1.773628	18.000032	736.483589	490.000000
-8.534479	16.098424	-1.773628	18.000032	731.746543	491.000000
-8.523897	16.008799	-1.773628	18.000032	727.672684	492.000000
-8.513315	15.898331	-1.773441	18.000032	722.651416	493.000000
-8.503791	15.800369	-1.773816	18.000032	718.198594	494.000000
-8.494268	15.698238	-1.773628	18.000032	713.556290	495.000000
-8.483686	15.529410	-1.773628	18.000032	705.882276	496.000000
-8.474162	15.506483	-1.773628	18.000032	704.840126	497.000000
-8.463580	15.389762	-1.774003	18.000032	699.534635	498.000000
-8.454057	15.254282	-1.773441	18.000032	693.376477	499.000000
-8.443475	15.164658	-1.773628	18.000032	689.302618	500.000000
-8.432893	15.031262	-1.773628	18.000032	683.239200	501.000000
-8.424428	14.939553	-1.773628	18.000032	679.070600	502.000000
-8.413846	14.860350	-1.773628	18.000032	675.470445	503.000000
-8.404322	14.697774	-1.773628	18.000032	668.080655	504.000000
-8.393740	14.591475	-1.773628	18.000032	663.248869	505.000000
-8.384216	14.439321	-1.773628	18.000032	656.332783	506.000000
-8.373635	14.314263	-1.773628	18.000032	650.648328	507.000000
-8.364111	14.147519	-1.773628	18.000032	643.069056	508.000000
-8.354587	-0.025533	-1.773628	9.462782	-1.160576	509.000000
-8.344005	-0.025533	-1.773254	9.486956	-1.160576	510.000000
-8.333424	-0.026054	-1.773254	9.548525	-1.184261	511.000000
-8.323900	-0.028138	-1.773628	9.616138	-1.279002	512.000000
-8.314376	-0.028659	-1.773628	9.671285	-1.302687	513.000000
-8.309085	-0.026575	-1.773628	9.704525	-1.207947	513.500000