File: Code/Example GUIs/Stress-Strain analyzer/SS_Data/4140/4140-1d1.txt
*
POSN mm 	LOAD kn	STRAIN1 %	STRAIN2 %	STRESS(MPA)	TIME(sec)
-6.722209	0.003648	-1.723129	0.012229	0.048804	0.000000
-6.712156	0.230836	-1.722942	0.017281	3.088586	1.000000
-6.702103	0.352768	-1.723129	0.019028	4.720028	2.000000
-6.691522	0.454898	-1.723316	0.018934	6.086535	3.000000
-6.682527	0.697198	-1.723316	0.023089	9.328504	4.000000
-6.672474	0.974931	-1.723316	0.027621	13.044568	5.000000
-6.662951	1.278197	-1.723316	0.033665	17.102258	6.000000
-6.652369	1.603869	-1.723316	0.039945	21.459743	7.000000
-6.642845	1.907656	-1.723129	0.045941	25.524405	8.000000
-6.633321	2.203626	-1.723316	0.052598	29.484488	9.000000
-6.623269	2.543367	-1.722942	0.059822	34.030217	10.000000
-6.613216	2.877897	-1.723316	0.066669	38.506225	11.000000
-6.602634	3.189500	-1.723129	0.073892	42.675467	12.000000
-6.592581	3.497976	-1.723129	0.080880	46.802877	13.000000
-6.581470	3.812706	-1.723129	0.087396	51.013951	14.000000
-6.572476	4.117013	-1.722755	0.094667	55.085585	15.000000
-6.562423	4.420279	-1.723129	0.101277	59.143276	16.000000
-6.552899	4.728755	-1.723129	0.107982	63.270686	17.000000
-6.542846	5.013262	-1.723129	0.114875	67.077385	18.000000
-6.532794	5.304022	-1.723129	0.121108	70.967747	19.000000
-6.522212	5.543196	-1.723129	0.126774	74.167885	20.000000
-6.512688	5.817802	-1.723316	0.133195	77.842116	21.000000
-6.502635	6.070002	-1.723316	0.139427	81.216553	22.000000
-6.492583	6.291980	-1.723316	0.144527	84.186615	23.000000
-6.482530	6.534801	-1.723129	0.150334	87.435556	24.000000
-6.471419	6.664028	-1.722942	0.153403	89.164606	25.000000
-6.462953	6.985010	-1.723503	0.161146	93.459343	26.000000
-6.452372	7.205425	-1.723316	0.165962	96.408489	27.000000
-6.442319	7.431571	-1.723129	0.171817	99.434327	28.000000
-6.432266	7.664492	-1.722755	0.177672	102.550800	29.000000
-6.422213	7.879696	-1.723129	0.182299	105.430227	30.000000
-6.412161	8.081352	-1.723316	0.187209	108.128381	31.000000
-6.402637	8.314793	-1.723129	0.192309	111.251827	32.000000
-6.392055	8.529476	-1.722755	0.197880	114.124281	33.000000
-6.382531	8.752496	-1.723129	0.203074	117.108287	34.000000
-6.372479	8.958842	-1.723503	0.208362	119.869190	35.000000
-6.362955	9.167272	-1.723316	0.212894	122.657980	36.000000
-6.352902	9.380913	-1.723129	0.217805	125.516491	37.000000
-6.342320	9.592990	-1.723129	0.223282	128.354085	38.000000
-6.331738	9.805068	-1.723129	0.228948	131.191679	39.000000
-6.322215	10.011830	-1.723129	0.233716	133.958159	40.000000
-6.313220	10.207755	-1.723129	0.237919	136.579623	41.000000
-6.302109	10.387004	-1.723129	0.242546	138.977982	42.000000
-6.292586	10.636078	-1.723129	0.248495	142.310587	43.000000
-6.282533	10.840340	-1.723129	0.253972	145.043602	44.000000
-6.272480	11.041475	-1.723129	0.258410	147.734785	45.000000
-6.261898	11.248862	-1.723316	0.263320	150.509631	46.000000
-6.253433	11.432281	-1.723129	0.268514	152.963767	47.000000
-6.242851	11.635500	-1.723316	0.273708	155.682838	48.000000
-6.232798	11.857478	-1.723503	0.279185	158.652900	49.000000
-6.222216	12.062782	-1.722942	0.284520	161.399858	50.000000
-6.212693	12.263917	-1.723129	0.289100	164.091041	51.000000
-6.204227	12.392101	-1.723129	0.292972	165.806148	52.000000
-6.192058	12.651596	-1.723316	0.299771	169.278192	53.000000
-6.182534	12.872532	-1.723316	0.305437	172.234310	54.000000
-6.172481	13.078878	-1.722381	0.311102	174.995212	55.000000
-6.162429	13.270633	-1.723503	0.316768	177.560900	56.000000
-6.152905	13.483232	-1.723129	0.321915	180.405466	57.000000
-6.142323	13.687493	-1.723129	0.327722	183.138481	58.000000
-6.132800	13.851111	-1.723316	0.333388	185.327681	59.000000
-6.122747	14.085595	-1.723316	0.340093	188.465071	60.000000
-6.112694	14.283603	-1.723129	0.346042	191.114422	61.000000
-6.103170	14.492033	-1.723129	0.351330	193.903212	62.000000
-6.092588	14.677536	-1.723129	0.358129	196.385236	63.000000
-6.083065	14.856786	-1.723129	0.364597	198.783596	64.000000
-6.073541	15.071469	-1.723129	0.371632	201.656050	65.000000
-6.062959	15.273646	-1.722942	0.378243	204.361177	66.000000
-6.053436	15.444558	-1.723316	0.384758	206.647985	67.000000
-6.042854	15.642567	-1.723129	0.391888	209.297336	68.000000
-6.033330	15.814521	-1.722942	0.399490	211.598088	69.000000
-6.022748	15.981265	-1.723129	0.406525	213.829121	70.000000
-6.012166	16.185527	-1.723129	0.414598	216.562135	71.000000
-6.002643	16.354355	-1.723129	0.423192	218.821056	72.000000
-5.992590	16.520057	-1.723503	0.431785	221.038144	73.000000
-5.982537	16.686801	-1.723129	0.440897	223.269177	74.000000
-5.973014	16.844166	-1.723129	0.449915	225.374714	75.000000
-5.962961	17.016120	-1.723129	0.459972	227.675466	76.000000
-5.952908	17.170359	-1.723129	0.471162	229.739171	77.000000
-5.942326	17.314175	-1.723503	0.482777	231.663436	78.000000
-5.933861	17.416306	-1.723316	0.494015	233.029944	79.000000
-5.922221	17.594514	-1.723129	0.508274	235.414360	80.000000
-5.912697	17.695602	-1.722942	0.521872	236.766923	81.000000
-5.903173	17.839419	-1.722755	0.538539	238.691188	82.000000
-5.893120	17.962393	-1.723316	0.555725	240.336575	83.000000
-5.883068	18.066608	-1.722942	0.574186	241.730970	84.000000
-5.872486	18.177075	-1.723129	0.594300	243.209029	85.000000
-5.861904	18.227099	-1.723129	0.615358	243.878339	86.000000
-5.853439	18.355283	-1.723129	0.639532	245.593445	87.000000
-5.842857	18.439697	-1.723316	0.664840	246.722905	88.000000
-5.833333	18.512648	-1.723316	0.691044	247.698982	89.000000
-5.823280	18.593935	-1.723316	0.719137	248.786610	90.000000
-5.811111	18.652296	-1.723129	0.749072	249.567472	91.000000
-5.802646	18.702319	-1.722942	0.779526	250.236781	92.000000
-5.792593	18.798197	-1.723129	0.811302	251.519625	93.000000
-5.782540	18.833630	-1.723129	0.845391	251.993719	94.000000
-5.773016	18.878442	-1.723129	0.878867	252.593309	95.000000
-5.762435	18.935761	-1.722755	0.915079	253.360227	96.000000
-5.751853	18.979531	-1.723129	0.951718	253.945873	97.000000
-5.742858	19.029554	-1.723316	0.988546	254.615182	98.000000
-5.732805	19.069156	-1.723316	1.027451	255.145053	99.000000
-5.722223	19.116053	-1.722942	1.064751	255.772531	100.000000
-5.713758	19.160865	-1.722755	1.102335	256.372121	101.000000
-5.703176	19.196298	-1.723129	1.140768	256.846215	102.000000
-5.694711	19.211930	-1.723316	1.177124	257.055374	103.000000
-5.683600	19.285923	-1.723503	1.216501	258.045395	104.000000
-5.673018	19.327609	-1.723316	1.255218	258.603153	105.000000
-5.663494	19.350536	-1.723129	1.292990	258.909920	106.000000
-5.652912	19.400559	-1.723129	1.328874	259.579230	107.000000
-5.641801	19.415150	-1.722942	1.367213	259.774445	108.000000
-5.633336	19.469341	-1.723503	1.405174	260.499531	109.000000
-5.622754	19.511027	-1.723316	1.443418	261.057289	110.000000
-5.613230	19.545418	-1.723129	1.481852	261.517439	111.000000
-5.602649	19.583978	-1.723129	1.519057	262.033365	112.000000
-5.593125	19.596484	-1.723316	1.557019	262.200693	113.000000
-5.582543	19.631917	-1.723316	1.594791	262.674787	114.000000
-5.573019	19.696530	-1.723129	1.632941	263.539312	115.000000
-5.562967	19.727795	-1.723129	1.670524	263.957631	116.000000
-5.553443	19.761143	-1.723129	1.708108	264.403837	117.000000
-5.543390	19.794492	-1.723503	1.746635	264.850044	118.000000
-5.531750	19.819504	-1.723129	1.783841	265.184699	119.000000
-5.523285	19.829925	-1.723316	1.817175	265.324138	120.000000
-5.512703	19.890370	-1.723316	1.857421	266.132887	121.000000
-5.502650	19.929972	-1.723129	1.894816	266.662758	122.000000
-5.492597	19.963320	-1.723316	1.932588	267.108964	123.000000
-5.482544	19.994585	-1.723316	1.969038	267.527283	124.000000
-5.472492	20.004402	-1.723129	2.006055	267.658635	125.000000
-5.462968	20.062762	-1.723129	2.044394	268.439496	126.000000
-5.453444	20.100280	-1.723316	2.080844	268.941479	127.000000
-5.442862	20.114870	-1.723129	2.118428	269.136694	128.000000
-5.433339	20.160725	-1.723129	2.156578	269.750228	129.000000
-5.423286	20.171146	-1.723316	2.192839	269.889667	130.000000
-5.413233	20.204495	-1.722755	2.230234	270.335874	131.000000
-5.403181	20.246181	-1.722942	2.266873	270.893632	132.000000
-5.392070	20.283698	-1.723129	2.303890	271.395614	133.000000
-5.382546	20.325384	-1.723129	2.339396	271.953372	134.000000
-5.372493	20.337890	-1.722942	2.377546	272.120700	135.000000
-5.362440	20.362902	-1.722755	2.414185	272.455355	136.000000
-5.352917	20.408756	-1.723129	2.450824	273.068889	137.000000
-5.343393	20.429599	-1.723316	2.487463	273.347768	138.000000
-5.333869	20.448358	-1.722755	2.524102	273.598759	139.000000
-5.323288	20.494212	-1.723503	2.561874	274.212293	140.000000
-5.313235	20.515055	-1.723129	2.597380	274.491172	141.000000
-5.303182	20.525477	-1.723316	2.633642	274.630611	142.000000
-5.293658	20.575500	-1.722942	2.669903	275.299921	143.000000
-5.283606	20.600512	-1.723503	2.705409	275.634576	144.000000
-5.273553	20.629692	-1.722942	2.742048	276.025007	145.000000
-5.263500	20.658872	-1.723129	2.778687	276.415437	146.000000
-5.252389	20.633861	-1.723316	2.813438	276.080782	147.000000
-5.243395	20.717233	-1.723129	2.850832	277.196299	148.000000
-5.233342	20.742244	-1.723503	2.888227	277.530954	149.000000
-5.222760	20.752666	-1.723129	2.924488	277.670393	150.000000
-5.213236	20.796436	-1.723129	2.960750	278.256039	151.000000
-5.203183	20.808942	-1.723503	2.996633	278.423366	152.000000
-5.193131	20.827700	-1.723129	3.032895	278.674358	153.000000
-5.183607	20.875639	-1.723129	3.068778	279.315779	154.000000
-5.173025	20.892314	-1.723129	3.107684	279.538883	155.000000
-5.163501	20.913157	-1.723129	3.145078	279.817762	156.000000
-5.152920	20.942337	-1.723316	3.183606	280.208192	157.000000
-5.143396	20.954843	-1.723129	3.221567	280.375520	158.000000
-5.132814	20.994444	-1.723316	3.259151	280.905390	159.000000
-5.123290	21.017372	-1.723316	3.296923	281.212157	160.000000
-5.113767	21.034046	-1.722942	3.330918	281.435260	161.000000
-5.103185	21.063226	-1.723129	3.368501	281.825691	162.000000
-5.093132	21.084069	-1.723316	3.405707	282.104570	163.000000
-5.083079	21.075732	-1.723503	3.440835	281.993018	164.000000
-5.073556	21.129924	-1.723316	3.479741	282.718104	165.000000
-5.062974	21.154936	-1.723129	3.516946	283.052759	166.000000
-5.052921	21.175779	-1.723316	3.554907	283.331638	167.000000
-5.042868	21.192453	-1.723503	3.592680	283.554741	168.000000
-5.032286	21.200790	-1.723503	3.630830	283.666293	169.000000
-5.023292	21.244560	-1.723129	3.669063	284.251939	170.000000
-5.013239	21.257066	-1.723129	3.707591	284.419266	171.000000
-5.002657	21.275825	-1.723129	3.744607	284.670257	172.000000
-4.993134	21.309174	-1.723316	3.783513	285.116464	173.000000
-4.981494	21.271656	-1.723129	3.820907	284.614482	174.000000
-4.974086	21.325848	-1.723129	3.859813	285.339567	175.000000
-4.962975	21.375871	-1.723316	3.900607	286.008877	176.000000
-4.953452	21.384209	-1.723316	3.940268	286.120428	177.000000
-4.943399	21.396714	-1.723129	3.978040	286.287756	178.000000
-4.932817	21.419642	-1.723129	4.017323	286.594523	179.000000
-4.923822	21.434232	-1.723503	4.056606	286.789738	180.000000
-4.913770	21.425895	-1.723129	4.092490	286.678187	181.000000
-4.903717	21.469665	-1.723316	4.133662	287.263833	182.000000
-4.893664	21.492592	-1.723129	4.172945	287.570599	183.000000
-4.883082	21.511351	-1.723316	4.212984	287.821591	184.000000
-4.873559	21.530110	-1.723129	4.252644	288.072582	185.000000
-4.862977	21.519688	-1.722942	4.292305	287.933142	186.000000
-4.852924	21.567627	-1.723129	4.333099	288.574564	187.000000
-4.842871	21.600976	-1.723129	4.369361	289.020771	188.000000
-4.833348	21.592639	-1.722942	4.409399	288.909219	189.000000
-4.822766	21.609313	-1.723316	4.449438	289.132322	190.000000
-4.812184	21.603060	-1.723129	4.488721	289.048658	191.000000
-4.803189	21.642662	-1.723503	4.528004	289.578529	192.000000
-4.793137	21.659336	-1.723503	4.568798	289.801632	193.000000
-4.782555	21.676011	-1.723129	4.608837	290.024735	194.000000
-4.773031	21.692685	-1.723316	4.647365	290.247838	195.000000
-4.763507	21.701022	-1.723316	4.687403	290.359390	196.000000
-4.752925	21.709359	-1.722755	4.726309	290.470942	197.000000
-4.743931	21.742708	-1.723316	4.766347	290.917148	198.000000
-4.733878	21.748961	-1.722942	4.807519	291.000812	199.000000
-4.723825	21.759383	-1.723503	4.847558	291.140251	200.000000
-4.714302	21.767720	-1.723129	4.887596	291.251803	201.000000
-4.704249	21.792731	-1.723316	4.927257	291.586458	202.000000
-4.693667	21.792731	-1.723503	4.967674	291.586458	203.000000
-4.683085	21.811490	-1.723503	5.009223	291.837449	204.000000
-4.673562	21.826080	-1.722942	5.050395	292.032664	205.000000
-4.662980	21.842755	-1.723129	5.092322	292.255768	206.000000
-4.653456	21.846923	-1.723129	5.134249	292.311543	207.000000
-4.642874	21.826080	-1.723129	5.175421	292.032664	208.000000
-4.633350	21.882356	-1.723316	5.218482	292.785638	209.000000
-4.623827	21.886525	-1.723316	5.261542	292.841414	210.000000
-4.613245	21.894862	-1.723316	5.304602	292.952965	211.000000
-4.603721	21.917789	-1.723129	5.348418	293.259732	212.000000
-4.592081	21.917789	-1.722942	5.389212	293.259732	213.000000
-4.583616	21.921958	-1.723316	5.433028	293.315508	214.000000
-4.573034	21.959475	-1.722942	5.471178	293.817490	215.000000
-4.564039	21.959475	-1.723503	5.516127	293.817490	216.000000
-4.553457	21.969897	-1.723316	5.559187	293.956930	217.000000
-4.543934	21.976150	-1.722942	5.603003	294.040594	218.000000
-4.533881	21.976150	-1.723129	5.645686	294.040594	219.000000
-4.523299	22.003246	-1.723129	5.689880	294.403136	220.000000
-4.513246	22.009499	-1.723129	5.734451	294.486800	221.000000
-4.504252	22.005330	-1.723129	5.776378	294.431024	222.000000
-4.493141	22.026173	-1.723316	5.821327	294.709903	223.000000
-4.483088	22.030342	-1.723316	5.865143	294.765679	224.000000
-4.473564	22.005330	-1.723129	5.908203	294.431024	225.000000
-4.464570	22.051185	-1.723316	5.953908	295.044558	226.000000
-4.453988	22.055353	-1.723503	5.998101	295.100334	227.000000
-4.443935	22.063690	-1.723129	6.043428	295.211886	228.000000
-4.434412	22.076196	-1.723129	6.086488	295.379213	229.000000
-4.424888	22.067859	-1.723129	6.131060	295.267661	230.000000
-4.414306	22.090786	-1.723316	6.176386	295.574428	231.000000
-4.403724	22.097039	-1.723503	6.221713	295.658092	232.000000
-4.393142	22.099123	-1.722568	6.268551	295.685980	233.000000
-4.383619	22.115798	-1.723129	6.313878	295.909083	234.000000
-4.371979	22.088702	-1.723129	6.359204	295.546540	235.000000
-4.363513	22.109545	-1.723316	6.404909	295.825420	236.000000
-4.353460	22.130388	-1.723129	6.451746	296.104299	237.000000
-4.343408	22.136641	-1.722942	6.498206	296.187962	238.000000
-4.333355	22.138725	-1.723316	6.543533	296.215850	239.000000
-4.323302	22.151231	-1.723503	6.591881	296.383178	240.000000
-4.313778	22.144978	-1.723129	6.637964	296.299514	241.000000
-4.304255	22.092871	-1.723129	6.673470	295.602316	242.000000
-4.293673	22.163737	-1.723316	6.728617	296.550505	243.000000
-4.284149	22.163737	-1.723503	6.776588	296.550505	244.000000
-4.274096	22.178327	-1.723316	6.823803	296.745720	245.000000
-4.264044	22.178327	-1.722942	6.869885	296.745720	246.000000
-4.254520	22.151231	-1.723129	6.915590	296.383178	247.000000
-4.243938	22.188748	-1.723129	6.965072	296.885160	248.000000
-4.233885	22.192917	-1.723129	7.010398	296.940936	249.000000
-4.223833	22.190833	-1.723503	7.057236	296.913048	250.000000
-4.213251	22.201254	-1.723316	7.104829	297.052487	251.000000
-4.203727	22.180411	-1.723316	7.152044	296.773608	252.000000
-4.193674	22.209591	-1.723503	7.200771	297.164039	253.000000
-4.183622	22.203338	-1.723316	7.248364	297.080375	254.000000
-4.174098	22.213760	-1.723129	7.297468	297.219815	255.000000
-4.163516	22.217929	-1.723129	7.342794	297.275591	256.000000
-4.153992	22.213760	-1.723129	7.391521	297.219815	257.000000
-4.143411	22.209591	-1.723316	7.440247	297.164039	258.000000
-4.133887	22.232519	-1.723129	7.488973	297.470806	259.000000
-4.124363	22.228350	-1.723129	7.539966	297.415030	260.000000
-4.113781	22.220013	-1.723129	7.590580	297.303478	261.000000
-4.103729	22.226266	-1.723316	7.641951	297.387142	262.000000
-4.093676	22.226266	-1.723129	7.691055	297.387142	263.000000
-4.083623	22.226266	-1.723129	7.742047	297.387142	264.000000
-4.073570	22.234603	-1.723316	7.794551	297.498694	265.000000
-4.064576	22.234603	-1.722942	7.845921	297.498694	266.000000
-4.053465	22.242940	-1.723503	7.897291	297.610245	267.000000
-4.043941	22.236687	-1.723129	7.950172	297.526582	268.000000
-4.033359	22.155400	-1.723129	7.995499	296.438953	269.000000
-4.024365	22.247109	-1.723129	8.050647	297.666021	270.000000
-4.014312	22.242940	-1.723129	8.103150	297.610245	271.000000
-4.003730	22.242940	-1.723316	8.156031	297.610245	272.000000
-3.993677	22.242940	-1.723129	8.208535	297.610245	273.000000
-3.983625	22.234603	-1.723316	8.260661	297.498694	274.000000
-3.973043	22.242940	-1.723129	8.312786	297.610245	275.000000
-3.963519	22.242940	-1.723129	8.364157	297.610245	276.000000
-3.953466	22.242940	-1.723129	8.416282	297.610245	277.000000
-3.943943	22.242940	-1.723316	8.469164	297.610245	278.000000
-3.933890	22.242940	-1.723129	8.521667	297.610245	279.000000
-3.924895	22.230434	-1.723316	8.574548	297.442918	280.000000
-3.913784	22.242940	-1.723129	8.627052	297.610245	281.000000
-3.904261	22.242940	-1.723316	8.680688	297.610245	282.000000
-3.893679	22.242940	-1.723503	8.732814	297.610245	283.000000
-3.884155	22.236687	-1.723316	8.787962	297.526582	284.000000
-3.874102	22.242940	-1.723129	8.844620	297.610245	285.000000
-3.864050	22.203338	-1.723316	8.898634	297.080375	286.000000
-3.854526	22.232519	-1.723129	8.957181	297.470806	287.000000
-3.843944	22.232519	-1.723503	9.015728	297.470806	288.000000
-3.833362	22.234603	-1.723129	9.074275	297.498694	289.000000
-3.823838	22.226266	-1.723129	9.131689	297.387142	290.000000
-3.814844	22.201254	-1.723503	9.187592	297.052487	291.000000
-3.803733	22.226266	-1.722942	9.246517	297.387142	292.000000
-3.793680	22.217929	-1.723316	9.304309	297.275591	293.000000
-3.783627	22.209591	-1.723503	9.362856	297.164039	294.000000
-3.773575	22.209591	-1.722942	9.423291	297.164039	295.000000
-3.762464	22.147062	-1.723129	9.476172	296.327402	296.000000
-3.753998	22.201254	-1.723503	9.538119	297.052487	297.000000
-3.743945	22.203338	-1.723129	9.597044	297.080375	298.000000
-3.733893	22.195001	-1.723316	9.657479	296.968824	299.000000
-3.723840	22.197086	-1.723503	9.715649	296.996712	300.000000
-3.714845	22.186664	-1.723129	9.776084	296.857272	301.000000
-3.704264	22.176243	-1.723129	9.835764	296.717832	302.000000
-3.693682	22.182495	-1.723316	9.894689	296.801496	303.000000
-3.684158	22.176243	-1.722942	9.955503	296.717832	304.000000
-3.673576	22.163737	-1.723129	10.017071	296.550505	305.000000
-3.664052	22.163737	-1.723316	10.079773	296.550505	306.000000
-3.654529	22.161652	-1.723129	10.141720	296.522617	307.000000
-3.643947	22.126219	-1.723129	10.203289	296.048523	308.000000
-3.634423	22.147062	-1.722942	10.268635	296.327402	309.000000
-3.623841	22.149147	-1.723129	10.329826	296.355290	310.000000
-3.614318	22.136641	-1.723316	10.394039	296.187962	311.000000
-3.603736	22.122051	-1.723129	10.458629	295.992747	312.000000
-3.594741	22.086618	-1.723129	10.522464	295.518653	313.000000
-3.583630	22.109545	-1.722942	10.586677	295.825420	314.000000
-3.574107	22.101208	-1.723129	10.651646	295.713868	315.000000
-3.563525	22.088702	-1.723503	10.717369	295.546540	316.000000
-3.554001	22.084533	-1.723129	10.780827	295.490765	317.000000
-3.544477	22.076196	-1.722942	10.846928	295.379213	318.000000
-3.533896	22.049100	-1.723129	10.912274	295.016670	319.000000
-3.524372	22.055353	-1.723316	10.977998	295.100334	320.000000
-3.514848	22.051185	-1.723129	11.044477	295.044558	321.000000
-3.504266	22.034510	-1.723129	11.110956	294.821455	322.000000
-3.495801	21.976150	-1.723129	11.175925	294.040594	323.000000
-3.484161	22.022004	-1.723316	11.241271	294.654127	324.000000
-3.474108	22.009499	-1.723129	11.308883	294.486800	325.000000
-3.464055	21.992824	-1.723503	11.377251	294.263697	326.000000
-3.454003	21.988656	-1.723129	11.444863	294.207921	327.000000
-3.443950	21.976150	-1.723129	11.511343	294.040594	328.000000
-3.434426	21.961560	-1.723129	11.579333	293.845378	329.000000
-3.423844	21.894862	-1.723129	11.643923	292.952965	330.000000
-3.413792	21.938632	-1.723129	11.712669	293.538611	331.000000
-3.403739	21.928211	-1.723129	11.780281	293.399172	332.000000
-3.394744	21.896946	-1.723316	11.849782	292.980853	333.000000
-3.384162	21.909452	-1.722942	11.916639	293.148181	334.000000
-3.374110	21.871935	-1.723129	11.985007	292.646198	335.000000
-3.364586	21.859429	-1.723129	12.053752	292.478871	336.000000
-3.354533	21.876103	-1.723129	12.118721	292.701974	337.000000
-3.344480	21.836502	-1.723129	12.187844	292.172104	338.000000
-3.333899	21.826080	-1.723316	12.257723	292.032664	339.000000
-3.324375	21.809406	-1.722755	12.327601	291.809561	340.000000
-3.313793	21.784394	-1.723316	18.000032	291.474906	341.000000
-3.304269	21.788563	-1.723316	18.000032	291.530682	342.000000
-3.293687	21.767720	-1.723316	18.000032	291.251803	343.000000
-3.284164	21.746877	-1.723129	18.000032	290.972924	344.000000
-3.274111	21.738540	-1.722942	18.000032	290.861372	345.000000
-3.264587	21.711444	-1.723316	18.000032	290.498830	346.000000
-3.254535	21.678095	-1.722755	18.000032	290.052623	347.000000
-3.243953	21.686432	-1.723503	18.000032	290.164175	348.000000
-3.234429	21.676011	-1.723129	18.000032	290.024735	349.000000
-3.224905	21.603060	-1.723316	18.000032	289.048658	350.000000
-3.214853	21.646830	-1.723503	18.000032	289.634304	351.000000
-3.203742	21.603060	-1.723129	18.000032	289.048658	352.000000
-3.194218	21.605144	-1.723503	18.000032	289.076546	353.000000
-3.183636	21.594723	-1.723316	18.000032	288.937107	354.000000
-3.174112	21.565543	-1.723316	18.000032	288.546676	355.000000
-3.163298	21.538447	-1.723503	18.000032	288.184133	356.000000
-3.154568	21.532194	-1.723316	18.000032	288.100470	357.000000
-3.144250	21.513435	-1.723129	18.000032	287.849479	358.000000
-3.134462	21.496761	-1.723129	18.000032	287.626375	359.000000
-3.124145	21.475918	-1.722942	18.000032	287.347496	360.000000
-3.114357	21.455075	-1.723129	18.000032	287.068617	361.000000
-3.104039	21.434232	-1.723316	18.000032	286.789738	362.000000
-3.094251	21.425895	-1.723316	18.000032	286.678187	363.000000
-3.084198	21.405052	-1.723316	18.000032	286.399307	364.000000
-3.074410	21.377956	-1.723503	18.000032	286.036765	365.000000
-3.064357	21.375871	-1.723316	18.000032	286.008877	366.000000
-3.054305	21.342523	-1.723316	18.000032	285.562670	367.000000
-3.044781	21.325848	-1.723129	18.000032	285.339567	368.000000
-3.034199	21.300837	-1.723129	18.000032	285.004912	369.000000
-3.024411	21.284162	-1.723129	18.000032	284.781809	370.000000
-3.014358	21.267488	-1.723503	18.000032	284.558706	371.000000
-3.003776	21.244560	-1.723129	18.000032	284.251939	372.000000
-2.993988	21.200790	-1.723129	18.000032	283.666293	373.000000
-2.984200	21.209127	-1.723316	18.000032	283.777844	374.000000
-2.974676	21.179947	-1.723129	18.000032	283.387414	375.000000
-2.964623	21.159104	-1.722942	18.000032	283.108535	376.000000
-2.954306	21.150767	-1.723129	18.000032	282.996983	377.000000
-2.944782	21.115334	-1.723316	18.000032	282.522889	378.000000
-2.934201	21.096575	-1.722755	18.000032	282.271897	379.000000
-2.924148	21.075732	-1.723129	18.000032	281.993018	380.000000
-2.914360	21.052805	-1.723129	18.000032	281.686251	381.000000
-2.903778	21.042383	-1.723129	18.000032	281.546812	382.000000
-2.893990	21.009035	-1.723503	18.000032	281.100605	383.000000
-2.883937	20.977770	-1.723503	18.000032	280.682287	384.000000
-2.874413	20.967349	-1.722942	18.000032	280.542847	385.000000
-2.864625	20.944421	-1.723129	18.000032	280.236080	386.000000
-2.854308	20.917325	-1.723129	18.000032	279.873538	387.000000
-2.844784	20.892314	-1.723316	18.000032	279.538883	388.000000
-2.834202	20.875639	-1.723129	18.000032	279.315779	389.000000
-2.824678	20.821448	-1.723129	18.000032	278.590694	390.000000
-2.814097	20.825616	-1.723503	18.000032	278.646470	391.000000
-2.804308	20.804773	-1.723316	18.000032	278.367591	392.000000
-2.794520	20.777677	-1.723503	18.000032	278.005048	393.000000
-2.784467	20.754750	-1.723503	18.000032	277.698281	394.000000
-2.774944	20.733907	-1.723503	18.000032	277.419402	395.000000
-2.764362	20.708895	-1.722755	18.000032	277.084747	396.000000
-2.754574	20.679715	-1.723316	18.000032	276.694316	397.000000
-2.744256	20.663041	-1.723316	18.000032	276.471213	398.000000
-2.734204	20.642198	-1.723316	18.000032	276.192334	399.000000
-2.723093	20.610933	-1.723503	18.000032	275.774015	400.000000
-2.714363	20.592175	-1.723316	18.000032	275.523024	401.000000
-2.704574	20.567163	-1.723503	18.000032	275.188369	402.000000
-2.695051	20.540067	-1.723503	18.000032	274.825827	403.000000
-2.684469	20.525477	-1.723316	18.000032	274.630611	404.000000
-2.674681	20.487960	-1.723503	18.000032	274.128629	405.000000
-2.664628	20.467117	-1.723129	18.000032	273.849750	406.000000
-2.654311	20.442105	-1.723316	18.000032	273.515095	407.000000
-2.644258	20.412925	-1.723129	18.000032	273.124664	408.000000
-2.634205	20.377492	-1.723316	18.000032	272.650570	409.000000
-2.624152	20.364986	-1.723129	18.000032	272.483243	410.000000
-2.614629	20.337890	-1.722755	18.000032	272.120700	411.000000
-2.604576	20.308710	-1.723503	18.000032	271.730269	412.000000
-2.594523	20.277445	-1.723503	18.000032	271.311951	413.000000
-2.584470	20.246181	-1.723316	18.000032	270.893632	414.000000
-2.574418	20.223253	-1.723129	18.000032	270.586865	415.000000
-2.564894	20.191989	-1.723316	18.000032	270.168546	416.000000
-2.553783	20.141966	-1.723316	18.000032	269.499237	417.000000
-2.544524	20.146134	-1.723503	18.000032	269.555013	418.000000
-2.534206	20.116954	-1.723129	18.000032	269.164582	419.000000
-2.524683	20.083605	-1.723129	18.000032	268.718375	420.000000
-2.514630	20.060678	-1.723129	18.000032	268.411608	421.000000
-2.505106	20.033582	-1.723316	18.000032	268.049066	422.000000
-2.494524	19.991896	-1.723129	18.000032	267.491308	423.000000
-2.484472	19.977306	-1.723129	18.000032	267.296092	424.000000
-2.474154	19.954379	-1.723129	18.000032	266.989325	425.000000
-2.464631	19.916861	-1.723316	18.000032	266.487343	426.000000
-2.454313	19.889766	-1.723316	18.000032	266.124800	427.000000
-2.443732	19.858501	-1.723316	18.000032	265.706482	428.000000
-2.435002	19.825152	-1.723316	18.000032	265.260275	429.000000
-2.424684	19.798056	-1.723316	18.000032	264.897732	430.000000
-2.415161	19.775129	-1.723129	18.000032	264.590965	431.000000
-2.404843	19.741780	-1.723503	18.000032	264.144759	432.000000
-2.394526	19.708431	-1.723503	18.000032	263.698552	433.000000
-2.384473	19.654240	-1.723503	18.000032	262.973467	434.000000
-2.374685	19.650071	-1.723316	18.000032	262.917691	435.000000
-2.364368	19.620891	-1.723503	18.000032	262.527260	436.000000
-2.354579	19.579205	-1.722942	18.000032	261.969502	437.000000
-2.344262	19.554193	-1.723503	18.000032	261.634847	438.000000
-2.334474	19.520844	-1.723316	18.000032	261.188641	439.000000
-2.324686	19.487496	-1.723316	18.000032	260.742434	440.000000
-2.315162	19.458315	-1.723129	18.000032	260.352004	441.000000
-2.305109	19.424967	-1.723503	18.000032	259.905797	442.000000
-2.295056	19.395786	-1.723129	18.000032	259.515367	443.000000
-2.285004	19.349932	-1.723129	18.000032	258.901833	444.000000
-2.275480	19.320752	-1.723316	18.000032	258.511402	445.000000
-2.264634	19.295740	-1.723316	18.000032	258.176747	446.000000
-2.254581	19.266560	-1.723316	18.000032	257.786316	447.000000
-2.244793	19.220705	-1.723503	18.000032	257.172783	448.000000
-2.234211	19.185272	-1.723316	18.000032	256.698688	449.000000
-2.224687	19.145670	-1.723129	18.000032	256.168818	450.000000
-2.215163	19.108153	-1.723129	18.000032	255.666836	451.000000
-2.204582	19.087310	-1.723316	18.000032	255.387957	452.000000
-2.194529	19.051877	-1.723129	18.000032	254.913862	453.000000
-2.185270	19.012275	-1.723316	18.000032	254.383992	454.000000
-2.174952	18.974758	-1.723316	18.000032	253.882010	455.000000
-2.164371	18.933072	-1.723316	18.000032	253.324252	456.000000
-2.155111	18.908060	-1.723503	18.000032	252.989597	457.000000
-2.145059	18.883049	-1.723129	18.000032	252.654942	458.000000
-2.134741	18.828857	-1.723316	18.000032	251.929856	459.000000
-2.125218	18.795508	-1.723129	18.000032	251.483650	460.000000
-2.115165	18.755906	-1.723316	18.000032	250.953780	461.000000
-2.104848	18.720473	-1.723503	18.000032	250.479685	462.000000
-2.095059	18.682956	-1.723129	18.000032	249.977703	463.000000
-2.084478	18.643354	-1.723503	18.000032	249.447833	464.000000
-2.074425	18.601668	-1.723129	18.000032	248.890075	465.000000
-2.064637	18.557898	-1.723129	18.000032	248.304429	466.000000
-2.054319	18.518296	-1.723129	18.000032	247.774558	467.000000
-2.044796	18.480779	-1.723129	18.000032	247.272576	468.000000
-2.034478	18.441177	-1.723129	18.000032	246.742706	469.000000
-2.024426	18.386985	-1.723316	18.000032	246.017620	470.000000
-2.014637	18.343215	-1.723316	18.000032	245.431974	471.000000
-2.004055	18.297360	-1.723316	18.000032	244.818440	472.000000
-1.995061	18.226494	-1.723316	18.000032	243.870252	473.000000
-1.985008	18.174387	-1.723316	18.000032	243.173054	474.000000
-1.974955	18.095183	-1.723316	18.000032	242.113314	475.000000
-1.964373	17.774201	-1.723316	18.000032	237.818576	476.000000
-1.954850	-0.095357	-1.723316	6.920123	-1.275872	477.000000
-1.945855	-0.098483	-1.723129	7.039483	-1.317704	478.000000
-1.935273	-0.093793	-1.723503	7.144868	-1.254956	479.000000
-1.929982	-0.092751	-1.723129	7.193972	-1.241012	479.500000