File: Code/Example GUIs/Stress-Strain analyzer/SS_Data/316/316-1d1.txt
*
POSN mm 	LOAD kn	STRAIN1 %	STRAIN2 %	STRESS(MPA)	TIME(sec)
15.044014	-0.019801	-1.770262	-0.003832	-0.900039	0.000000
15.073643	0.169870	-1.769701	-0.002133	7.721384	3.000000
15.104330	0.268875	-1.769888	-0.005107	12.221577	6.000000
15.135018	0.482515	-1.769701	-0.009734	21.932520	9.000000
15.164647	1.125522	-1.769888	-0.004541	51.160089	12.000000
15.194276	2.041051	-1.769701	0.008632	92.775032	15.000000
15.222847	2.947721	-1.769888	0.025441	133.987326	18.000000
15.253534	3.749656	-1.769888	0.044091	170.438889	21.000000
15.283164	4.586502	-1.769888	0.065244	208.477363	24.000000
15.314909	5.272237	-1.769701	0.087624	239.647121	27.000000
15.343480	5.864699	-1.769888	0.111042	266.577223	30.000000
15.373109	6.403490	-1.769514	0.137389	291.067747	33.000000
15.403797	6.871937	-1.769888	0.167795	312.360766	36.000000
15.433426	7.314330	-1.769888	0.202735	332.469523	39.000000
15.463055	7.689503	-1.769888	0.242207	349.522886	42.000000
15.492684	8.041750	-1.769888	0.284323	365.534099	45.000000
15.524430	8.242364	-1.770262	0.331821	374.652911	48.000000
15.551943	8.575331	-1.769701	0.385930	389.787771	51.000000
15.583688	8.792098	-1.769888	0.441880	399.640825	54.000000
15.613317	9.019287	-1.769888	0.502835	409.967584	57.000000
15.642947	9.221985	-1.769888	0.566293	419.181137	60.000000
15.672576	9.379871	-1.769888	0.635038	426.357760	63.000000
15.704321	9.529940	-1.769701	0.705578	433.179105	66.000000
15.733951	9.661251	-1.769888	0.781595	439.147782	69.000000
15.763580	9.830080	-1.769888	0.855912	446.821796	72.000000
15.795325	9.853007	-1.769888	0.940519	447.863946	75.000000
15.822838	9.995781	-1.769888	1.027773	454.353698	78.000000
15.853526	10.044137	-1.770075	1.115971	456.551687	81.000000
15.884213	10.156689	-1.769888	1.209458	461.667696	84.000000
15.913842	10.202544	-1.769514	1.300300	463.751996	87.000000
15.943471	10.302590	-1.769701	1.398697	468.299559	90.000000
15.973101	10.365119	-1.770262	1.496622	471.141786	93.000000
16.002730	10.444323	-1.769888	1.597096	474.741941	96.000000
16.032359	10.490177	-1.769701	1.692188	476.826241	99.000000
16.063046	10.500599	-1.769888	1.798328	477.299945	102.000000
16.092676	10.583971	-1.769888	1.899656	481.089581	105.000000
16.123363	10.646500	-1.769888	2.000886	483.931808	108.000000
16.152992	10.701734	-1.769888	2.102494	486.442442	111.000000
16.182621	10.723619	-1.769514	2.199946	487.437222	114.000000
16.214367	10.788232	-1.769701	2.301931	490.374190	117.000000
16.242938	10.812202	-1.769888	2.400517	491.463710	120.000000
16.273625	10.862225	-1.769888	2.499858	493.737492	123.000000
16.303254	10.731956	-1.769888	2.585601	487.816186	126.000000
16.332884	10.965398	-1.769888	2.695518	498.427167	129.000000
16.362513	11.002915	-1.769701	2.793160	500.132503	132.000000
16.392142	11.042517	-1.769888	2.891368	501.932581	135.000000
16.422829	11.086287	-1.769888	2.990142	503.922140	138.000000
16.452459	11.111299	-1.769888	3.088728	505.059030	141.000000
16.483146	11.148816	-1.769701	3.189580	506.764367	144.000000
16.513833	11.211345	-1.769888	3.287788	509.606594	147.000000
16.543463	11.232188	-1.769888	3.389017	510.554003	150.000000
16.574150	11.115467	-1.769514	3.481559	505.248512	153.000000
16.602721	11.296801	-1.769514	3.586566	513.490971	156.000000
16.633408	11.328066	-1.769514	3.685664	514.912085	159.000000
16.663038	11.367668	-1.769888	3.784627	516.712162	162.000000
16.692667	11.382258	-1.769701	3.883590	517.375348	165.000000
16.723354	11.448955	-1.769888	3.982176	520.407057	168.000000
16.752983	11.490641	-1.769701	4.081517	522.301875	171.000000
16.783671	11.530243	-1.769888	4.179725	524.101952	174.000000
16.813300	11.561507	-1.769701	4.278688	525.523066	177.000000
16.845046	11.398932	-1.769888	4.370097	518.133275	180.000000
16.872558	11.616741	-1.769888	4.472838	528.033700	183.000000
16.904304	11.632374	-1.769701	4.569913	528.744257	186.000000
16.933933	11.685523	-1.769888	4.666232	531.160150	189.000000
16.963562	11.669891	-1.769514	4.763307	530.449593	192.000000
16.993192	11.749094	-1.769514	4.858115	534.049748	195.000000
17.022821	11.757432	-1.769514	4.953301	534.428711	198.000000
17.052450	11.791823	-1.769888	5.049243	535.991936	201.000000
17.082079	11.830382	-1.770075	5.144051	537.744643	204.000000
17.115941	11.803286	-1.769514	5.240371	536.513011	207.000000
17.142396	11.899164	-1.769888	5.335557	540.871093	210.000000
17.172025	11.924176	-1.769701	5.430743	542.007984	213.000000
17.202712	11.967946	-1.769888	5.525174	543.997543	216.000000
17.234458	11.959609	-1.769514	5.619604	543.618579	219.000000
17.263029	12.024222	-1.769514	5.713279	546.555547	222.000000
17.293716	12.036728	-1.769701	5.806199	547.123992	225.000000
17.323345	12.076330	-1.769888	5.899497	548.924070	228.000000
17.352975	12.049234	-1.769888	5.991283	547.692438	231.000000
17.376255	11.957524	-1.769514	6.075516	543.523838	234.000000
17.412233	12.163870	-1.769888	6.171835	552.903188	237.000000
17.441862	12.203472	-1.770075	6.264377	554.703265	240.000000
17.473608	12.235778	-1.769888	6.355408	556.171749	243.000000
17.502179	12.247242	-1.769888	6.447572	556.692824	246.000000
17.532866	12.278507	-1.769888	6.536715	558.113938	249.000000
17.562495	12.308729	-1.770075	6.626235	559.487681	252.000000
17.592125	12.354584	-1.769701	6.715000	561.571981	255.000000
17.623870	12.292055	-1.769888	6.805654	558.729753	258.000000
17.652441	12.365005	-1.769514	6.896307	562.045685	261.000000
17.681012	12.374384	-1.769514	6.983183	562.472019	264.000000
17.712758	12.444208	-1.769888	7.073837	565.645840	267.000000
17.742387	12.446293	-1.769701	7.161468	565.740580	270.000000
17.772016	12.498400	-1.769888	7.251367	568.109103	273.000000
17.802704	12.532791	-1.769888	7.338243	569.672328	276.000000
17.832333	12.561971	-1.769888	7.425874	570.998701	279.000000
17.863020	12.592194	-1.769888	7.513506	572.372444	282.000000
17.890533	12.576562	-1.769888	7.601893	571.661887	285.000000
17.920162	12.529665	-1.769327	7.688392	569.530217	288.000000
17.951908	12.659934	-1.769888	7.773379	575.451523	291.000000
17.983653	12.693282	-1.769888	7.861011	576.967378	294.000000
18.010108	12.674524	-1.769888	7.947887	576.114710	297.000000
18.042912	12.726631	-1.769701	8.035519	578.483232	300.000000
18.072541	12.749558	-1.769888	8.120884	579.525382	303.000000
18.101112	12.786034	-1.769701	8.208516	581.183348	306.000000
18.131799	12.741221	-1.769514	8.292370	579.146419	309.000000
18.162487	12.840225	-1.769701	8.383779	583.646612	312.000000
18.191058	12.868364	-1.769701	8.469900	584.925614	315.000000
18.221745	12.893375	-1.769514	8.553755	586.062505	318.000000
18.251374	12.913176	-1.770075	8.640253	586.962543	321.000000
18.282062	12.907965	-1.769514	8.727507	586.725691	324.000000
18.311691	12.963199	-1.769888	8.814383	589.236325	327.000000
18.342378	12.988211	-1.769701	8.898615	590.373216	330.000000
18.370949	13.014264	-1.770075	8.984358	591.557477	333.000000
18.402695	12.941314	-1.769888	9.068968	588.241545	336.000000
18.430208	13.045529	-1.769888	9.158111	592.978591	339.000000
18.461953	13.053866	-1.769701	9.244232	593.357554	342.000000
18.491582	13.096594	-1.769888	9.327331	595.299743	345.000000
18.523328	13.138280	-1.769888	9.413452	597.194561	348.000000
18.551899	13.147660	-1.769514	9.499572	597.620895	351.000000
18.580470	13.168503	-1.769888	9.585315	598.568304	354.000000
18.611157	13.195599	-1.769701	9.670303	599.799936	357.000000
18.641845	13.214357	-1.769888	9.756046	600.652604	360.000000
18.669358	13.154955	-1.769327	9.840278	597.952488	363.000000
18.703220	13.258128	-1.769888	9.929421	602.642163	366.000000
18.732849	13.243537	-1.769888	10.014786	601.978977	369.000000
18.762478	13.287308	-1.769327	10.099396	603.968536	372.000000
18.792107	13.291476	-1.769888	10.184761	604.158018	375.000000
18.821736	13.343584	-1.769701	10.272393	606.526540	378.000000
18.851366	13.374848	-1.769888	10.357758	607.947654	381.000000
18.882053	13.404029	-1.769888	10.443879	609.274027	384.000000
18.910624	13.424872	-1.769888	10.528489	610.221436	387.000000
18.940253	13.376933	-1.769327	10.613854	608.042395	390.000000
18.971999	13.460305	-1.769888	10.701864	611.832031	393.000000
19.001628	13.474895	-1.769888	10.789118	612.495217	396.000000
19.033373	13.504075	-1.769514	10.870706	613.821590	399.000000
19.059828	13.486358	-1.769701	10.956449	613.016292	402.000000
19.091574	13.519707	-1.769514	11.042192	614.532147	405.000000
19.122261	13.501991	-1.769514	11.129068	613.726849	408.000000
19.151890	13.577025	-1.769701	11.212923	617.137522	411.000000
19.181519	13.547845	-1.769514	11.298288	615.811149	414.000000
19.211149	13.600995	-1.769514	11.387431	618.227042	417.000000
19.241836	13.635386	-1.769514	11.474307	619.790267	420.000000
19.272523	13.649976	-1.769701	11.559672	620.453453	423.000000
19.301094	13.682283	-1.769701	11.645038	621.921937	426.000000
19.331782	13.679156	-1.769514	11.731536	621.779826	429.000000
19.362469	13.709379	-1.769514	11.818790	623.153569	432.000000
19.391040	13.739601	-1.769701	11.904911	624.527312	435.000000
19.422786	13.761486	-1.769701	11.989143	625.522092	438.000000
19.452415	13.695831	-1.769701	12.074131	622.537753	441.000000
19.479928	13.760444	-1.769888	12.162140	625.474721	444.000000
19.509557	13.770865	-1.769701	12.249394	625.948426	447.000000
19.541303	13.810467	-1.769514	12.335892	627.748503	450.000000
19.571990	13.845900	-1.769514	18.000032	629.359098	453.000000
19.601619	13.858406	-1.769888	18.000032	629.927544	456.000000
19.632307	13.883418	-1.769514	18.000032	631.064435	459.000000
19.661936	13.896966	-1.769888	18.000032	631.680251	462.000000
19.691565	13.931356	-1.769701	18.000032	633.243476	465.000000
19.723310	13.900092	-1.769514	18.000032	631.822362	468.000000
19.751882	13.950115	-1.769701	18.000032	634.096144	471.000000
19.780452	13.939694	-1.769888	18.000032	633.622439	474.000000
19.810082	13.975127	-1.769888	18.000032	635.233035	477.000000
19.839711	13.954284	-1.769888	18.000032	634.285626	480.000000
19.871456	14.003265	-1.769888	18.000032	636.512037	483.000000
19.901086	14.025150	-1.769327	18.000032	637.506816	486.000000
19.930715	14.058499	-1.769888	18.000032	639.022671	489.000000
19.960344	14.031403	-1.769888	18.000032	637.791039	492.000000
19.994206	14.066836	-1.769888	18.000032	639.401634	495.000000
20.021719	14.091848	-1.769701	18.000032	640.538525	498.000000
20.051348	14.110606	-1.769327	18.000032	641.391193	501.000000
20.079919	14.136660	-1.769888	18.000032	642.575455	504.000000
20.110606	14.110606	-1.769701	18.000032	641.391193	507.000000
20.141294	14.175220	-1.769701	18.000032	644.328162	510.000000
20.169865	14.158545	-1.769888	18.000032	643.570234	513.000000
20.201610	14.187725	-1.769701	18.000032	644.896607	516.000000
20.231240	14.126239	-1.769701	18.000032	642.101750	519.000000
20.260869	14.225243	-1.770075	18.000032	646.601943	522.000000
20.290498	14.239833	-1.769514	18.000032	647.265130	525.000000
20.321185	14.264844	-1.769514	18.000032	648.402021	528.000000
20.351090	14.234622	-1.769888	18.000032	647.028277	531.000000
20.380719	14.291940	-1.769701	18.000032	649.633652	534.000000
20.410348	14.334668	-1.769701	18.000032	651.575841	537.000000
20.442094	14.337795	-1.769701	18.000032	651.717952	540.000000
20.471723	14.379481	-1.769514	18.000032	653.612770	543.000000
20.499236	14.300278	-1.769888	18.000032	650.012616	546.000000
20.537330	14.308615	-1.769888	18.000032	650.391580	549.000000
20.562727	14.354469	-1.769888	18.000032	652.475879	552.000000
20.592356	14.402408	-1.769514	18.000032	654.654920	555.000000
20.619869	14.358638	-1.769514	18.000032	652.665361	558.000000
20.651614	14.425336	-1.769514	18.000032	655.697070	561.000000
20.681244	14.479527	-1.769701	18.000032	658.160334	564.000000
20.710873	14.442010	-1.769327	18.000032	656.454997	567.000000
20.740502	14.414914	-1.769888	18.000032	655.223366	570.000000
20.770131	14.443052	-1.769888	18.000032	656.502368	573.000000
20.799760	14.473274	-1.769701	18.000032	657.876111	576.000000
20.829390	14.500370	-1.769514	18.000032	659.107743	579.000000
20.859019	14.529551	-1.769888	18.000032	660.434116	582.000000
20.890764	14.508708	-1.769701	18.000032	659.486706	585.000000
20.920394	14.553520	-1.769701	18.000032	661.523636	588.000000
20.947906	14.568110	-1.769514	18.000032	662.186822	591.000000
20.981768	14.593122	-1.769514	18.000032	663.323713	594.000000
21.011397	14.510792	-1.769888	18.000032	659.581447	597.000000
21.041027	14.568110	-1.769888	18.000032	662.186822	600.000000
21.070656	14.575405	-1.769888	18.000032	662.518415	603.000000
21.100285	14.659819	-1.769701	18.000032	666.355422	606.000000
21.132031	14.669199	-1.769888	18.000032	666.781756	609.000000
21.161660	14.652524	-1.769514	18.000032	666.023829	612.000000
21.191289	14.682747	-1.770262	18.000032	667.397572	615.000000
21.220918	14.730685	-1.769514	18.000032	669.576613	618.000000
21.250547	14.706716	-1.769701	18.000032	668.487092	621.000000
21.282293	14.599375	-1.769327	18.000032	663.607936	624.000000
21.309806	14.705674	-1.769888	18.000032	668.439722	627.000000
21.339435	14.725475	-1.769514	18.000032	669.339761	630.000000
21.371181	14.734854	-1.769888	18.000032	669.766095	633.000000
21.400810	14.715053	-1.769701	18.000032	668.866056	636.000000
21.428323	14.760908	-1.769888	18.000032	670.950356	639.000000
21.460068	14.772371	-1.769701	18.000032	671.471431	642.000000
21.491814	14.845322	-1.769888	18.000032	674.787363	645.000000
21.519327	14.844280	-1.769888	18.000032	674.739992	648.000000
21.548956	14.742149	-1.769701	18.000032	670.097688	651.000000
21.578585	14.844280	-1.769888	18.000032	674.739992	654.000000
21.610331	14.818226	-1.769888	18.000032	673.555731	657.000000
21.642076	14.850533	-1.769514	18.000032	675.024215	660.000000
21.671705	14.838027	-1.769888	18.000032	674.455770	663.000000
21.701335	14.868249	-1.769888	18.000032	675.829513	666.000000
21.728847	14.844280	-1.769888	18.000032	674.739992	669.000000
21.760593	15.046457	-1.769888	18.000032	683.929860	672.000000
21.790222	14.817184	-1.769701	18.000032	673.508360	675.000000
21.824084	14.833858	-1.769701	18.000032	674.266288	678.000000
21.849481	14.942242	-1.769514	18.000032	679.192815	681.000000
21.879110	14.934947	-1.769888	18.000032	678.861222	684.000000
21.908739	14.968296	-1.769888	18.000032	680.377076	687.000000
21.938368	14.918272	-1.769888	18.000032	678.103294	690.000000
21.970114	14.992265	-1.770075	18.000032	681.466597	693.000000
22.001859	14.976633	-1.769888	18.000032	680.756040	696.000000
22.029372	15.051668	-1.770075	18.000032	684.166712	699.000000
22.061118	14.927652	-1.769701	18.000032	678.529628	702.000000
22.090747	14.992265	-1.769888	18.000032	681.466597	705.000000
22.120376	15.011024	-1.769701	18.000032	682.319265	708.000000
22.150005	15.025614	-1.769514	18.000032	682.982451	711.000000
22.179634	15.058963	-1.769888	18.000032	684.498306	714.000000
22.211380	15.076679	-1.769888	18.000032	685.303603	717.000000
22.238893	15.102733	-1.769888	18.000032	686.487865	720.000000
22.270638	15.065216	-1.769701	18.000032	684.782528	723.000000
22.298151	15.209032	-1.769514	18.000032	691.319651	726.000000
22.327780	15.062089	-1.769888	18.000032	684.640417	729.000000
22.359526	15.075637	-1.769888	18.000032	685.256233	732.000000
22.391272	15.112112	-1.769514	18.000032	686.914199	735.000000
22.420901	15.137124	-1.769888	18.000032	688.051089	738.000000
22.450530	15.111070	-1.769514	18.000032	686.866828	741.000000
22.480159	15.142335	-1.769888	18.000032	688.287942	744.000000
22.509788	15.179852	-1.769701	18.000032	689.993278	747.000000
22.539418	15.197569	-1.769701	18.000032	690.798576	750.000000
22.569047	15.077721	-1.769888	18.000032	685.350974	753.000000
22.602909	15.170473	-1.769514	18.000032	689.566944	756.000000
22.630422	15.213201	-1.769514	18.000032	691.509133	759.000000
22.660051	15.195484	-1.769701	18.000032	690.703835	762.000000
22.689680	15.234044	-1.769701	18.000032	692.456542	765.000000
22.717193	15.204864	-1.769701	18.000032	691.130169	768.000000
22.751055	15.243423	-1.769701	18.000032	692.882876	771.000000
22.780684	15.243423	-1.769888	18.000032	692.882876	774.000000
22.808197	15.259056	-1.769514	18.000032	693.593432	777.000000
22.839942	15.096480	-1.769888	18.000032	686.203642	780.000000
22.869571	15.268435	-1.769888	18.000032	694.019767	783.000000
22.899201	15.298657	-1.769888	18.000032	695.393510	786.000000
22.928830	15.325753	-1.769514	18.000032	696.625141	789.000000
22.960575	15.339301	-1.769701	18.000032	697.240957	792.000000
22.990205	15.321585	-1.769888	18.000032	696.435660	795.000000
23.019834	15.352849	-1.769888	18.000032	697.856773	798.000000
23.049463	15.344512	-1.769701	18.000032	697.477810	801.000000
23.079092	15.359102	-1.769701	18.000032	698.140996	804.000000
23.110838	15.238213	-1.769888	18.000032	692.646023	807.000000
23.138351	15.362228	-1.769888	18.000032	698.283107	810.000000
23.170096	15.342428	-1.769888	18.000032	697.383069	813.000000
23.199725	15.385156	-1.769888	18.000032	699.325257	816.000000
23.229355	15.370566	-1.769888	18.000032	698.662071	819.000000
23.258984	15.414336	-1.769888	18.000032	700.651630	822.000000
23.288613	15.442474	-1.769701	18.000032	701.930632	825.000000
23.318242	15.448727	-1.769888	18.000032	702.214855	828.000000
23.349988	15.454980	-1.770262	18.000032	702.499078	831.000000
23.381733	15.281983	-1.769888	18.000032	694.635582	834.000000
23.409246	15.425800	-1.769888	18.000032	701.172705	837.000000
23.438875	15.450811	-1.769888	18.000032	702.309596	840.000000
23.470621	15.468528	-1.770262	18.000032	703.114893	843.000000
23.500250	15.417462	-1.769701	18.000032	700.793741	846.000000
23.529879	15.510214	-1.769888	18.000032	705.009712	849.000000
23.559509	15.492497	-1.769701	18.000032	704.204414	852.000000
23.589138	15.517509	-1.769701	18.000032	705.341305	855.000000
23.618767	15.500834	-1.769701	18.000032	704.583377	858.000000
23.652629	15.399746	-1.769888	18.000032	699.988444	861.000000
23.680142	15.546689	-1.769888	18.000032	706.667677	864.000000
23.707654	15.521677	-1.769888	18.000032	705.530787	867.000000
23.739400	15.544605	-1.770075	18.000032	706.572937	870.000000
23.766913	15.498750	-1.769888	18.000032	704.488637	873.000000
23.798658	15.580038	-1.769701	18.000032	708.183532	876.000000
23.828288	15.552942	-1.770075	18.000032	706.951900	879.000000
23.860033	15.577953	-1.769701	18.000032	708.088791	882.000000
23.887546	15.525846	-1.769701	18.000032	705.720268	885.000000
23.906593	15.351807	-1.769888	18.000032	697.809403	888.000000
23.948921	15.614429	-1.769888	18.000032	709.746757	891.000000
23.978550	15.638398	-1.769888	18.000032	710.836277	894.000000
24.008179	15.642567	-1.769888	18.000032	711.025759	897.000000
24.037808	15.592544	-1.769888	18.000032	708.751977	900.000000
24.069554	15.648820	-1.769888	18.000032	711.309982	903.000000
24.099183	15.650904	-1.769888	18.000032	711.404723	906.000000
24.128812	15.694674	-1.769701	18.000032	713.394282	909.000000
24.156325	15.572743	-1.769888	18.000032	707.851939	912.000000
24.185954	15.521677	-1.769701	18.000032	705.530787	915.000000
24.219816	15.655072	-1.769888	18.000032	711.594205	918.000000
24.247329	15.692590	-1.769701	18.000032	713.299541	921.000000
24.276958	15.667578	-1.769888	18.000032	712.162650	924.000000
24.308704	15.700927	-1.769888	18.000032	713.678504	927.000000
24.338333	15.700927	-1.769514	18.000032	713.678504	930.000000
24.370079	15.736360	-1.769514	18.000032	715.289100	933.000000
24.399708	15.778046	-1.769888	18.000032	717.183918	936.000000
24.427221	15.667578	-1.769888	18.000032	712.162650	939.000000
24.465315	15.662368	-1.769888	18.000032	711.925798	942.000000
24.490712	15.743655	-1.769701	18.000032	715.620693	945.000000
24.518225	15.771793	-1.769701	18.000032	716.899695	948.000000
24.545738	15.700927	-1.769888	18.000032	713.678504	951.000000
24.579599	15.763456	-1.770262	18.000032	716.520732	954.000000
24.609229	15.770751	-1.769888	18.000032	716.852325	957.000000
24.638858	15.792636	-1.769888	18.000032	717.847104	960.000000
24.668487	15.693632	-1.769701	18.000032	713.346911	963.000000
24.698116	15.750950	-1.769888	18.000032	715.952286	966.000000
24.727745	15.736360	-1.769701	18.000032	715.289100	969.000000
24.757375	15.817648	-1.769888	18.000032	718.983995	972.000000
24.791237	15.836407	-1.769888	18.000032	719.836663	975.000000
24.816633	15.792636	-1.769701	18.000032	717.847104	978.000000
24.848379	15.820774	-1.769514	18.000032	719.126106	981.000000
24.880124	15.844744	-1.769888	18.000032	720.215627	984.000000
24.909753	15.876008	-1.769888	18.000032	721.636740	987.000000
24.939383	15.728023	-1.769701	18.000032	714.910136	990.000000
24.966895	15.848912	-1.769888	18.000032	720.405109	993.000000
24.992292	15.772835	-1.769701	18.000032	716.947066	996.000000
25.028270	15.902062	-1.769888	18.000032	722.821002	999.000000
25.057899	15.892683	-1.769888	18.000032	722.394668	1002.000000
25.089645	15.913526	-1.769888	18.000032	723.342077	1005.000000
25.117158	15.904146	-1.770075	18.000032	722.915743	1008.000000
25.148903	15.902062	-1.769701	18.000032	722.821002	1011.000000
25.176416	15.940622	-1.770075	18.000032	724.573709	1014.000000
25.203929	15.814521	-1.769888	18.000032	718.841884	1017.000000
25.239907	15.938537	-1.769888	18.000032	724.478968	1020.000000
25.265304	15.892683	-1.769514	18.000032	722.394668	1023.000000
25.297049	15.921863	-1.769888	18.000032	723.721040	1026.000000
25.328795	15.926031	-1.769888	18.000032	723.910522	1029.000000
25.358424	15.959380	-1.769888	18.000032	725.426377	1032.000000
25.388053	15.978139	-1.769888	18.000032	726.279045	1035.000000
25.417682	16.009403	-1.769514	18.000032	727.700158	1038.000000
25.447312	16.009403	-1.769701	18.000032	727.700158	1041.000000
25.481174	15.878093	-1.769701	18.000032	721.731481	1044.000000
25.508686	16.001066	-1.769514	18.000032	727.321195	1047.000000
25.536199	15.907273	-1.769701	18.000032	723.057854	1050.000000
25.565828	16.017741	-1.769888	18.000032	728.079122	1053.000000
25.595458	15.992729	-1.769888	18.000032	726.942231	1056.000000
25.629320	16.026078	-1.769888	18.000032	728.458086	1059.000000
25.658949	16.009403	-1.769888	18.000032	727.700158	1062.000000
25.688578	16.067764	-1.769701	18.000032	730.352904	1065.000000
25.718207	15.980223	-1.769888	18.000032	726.373786	1068.000000
25.745720	15.965633	-1.769888	18.000032	725.710599	1071.000000
25.777466	16.051089	-1.769701	18.000032	729.594977	1074.000000
25.807095	16.072975	-1.769701	18.000032	730.589756	1077.000000
25.836724	16.090691	-1.769888	18.000032	731.395054	1080.000000
25.866353	16.061511	-1.770262	18.000032	730.068681	1083.000000
25.895982	16.076101	-1.769888	18.000032	730.731867	1086.000000
25.929844	16.092775	-1.769888	18.000032	731.489795	1089.000000
25.959474	16.131335	-1.769701	18.000032	733.242501	1092.000000
25.986986	16.044837	-1.769888	18.000032	729.310754	1095.000000
26.018732	16.043794	-1.769888	18.000032	729.263383	1098.000000
26.046245	16.076101	-1.769514	18.000032	730.731867	1101.000000
26.090689	15.992729	-1.769888	18.000032	726.942231	1104.000000
26.109736	16.132377	-1.769888	18.000032	733.289872	1107.000000
26.137249	16.134461	-1.769701	18.000032	733.384613	1110.000000
26.168994	16.165726	-1.769514	18.000032	734.805726	1113.000000
26.198623	16.159473	-1.769514	18.000032	734.521504	1116.000000
26.226136	16.209496	-1.769701	18.000032	736.795285	1119.000000
26.255766	16.129251	-1.769888	18.000032	733.147761	1122.000000
26.287511	16.126124	-1.769888	18.000032	733.005649	1125.000000
26.317140	16.151136	-1.769888	18.000032	734.142540	1128.000000
26.348886	16.160515	-1.769888	18.000032	734.568874	1131.000000
26.378515	16.134461	-1.769888	18.000032	733.384613	1134.000000
26.408144	16.189695	-1.769888	18.000032	735.895247	1137.000000
26.435657	16.177190	-1.770075	18.000032	735.326801	1140.000000
26.467403	16.220960	-1.769888	18.000032	737.316360	1143.000000
26.497032	16.142799	-1.769888	18.000032	733.763576	1146.000000
26.530894	16.148009	-1.769514	18.000032	734.000429	1149.000000
26.558407	16.230339	-1.769888	18.000032	737.742694	1152.000000
26.588036	16.194906	-1.769888	18.000032	736.132099	1155.000000
26.617665	16.219918	-1.769514	18.000032	737.268990	1158.000000
26.645178	16.188653	-1.769888	18.000032	735.847876	1161.000000
26.676923	16.236592	-1.769701	18.000032	738.026917	1164.000000
26.708669	16.201159	-1.769888	18.000032	736.416322	1167.000000
26.738298	16.231381	-1.769888	18.000032	737.790065	1170.000000
26.767927	16.167810	-1.769701	18.000032	734.900467	1173.000000
26.801789	16.217833	-1.769701	18.000032	737.174249	1176.000000
26.827186	16.276194	-1.769888	18.000032	739.826994	1179.000000
26.858931	16.287658	-1.769888	18.000032	740.348069	1182.000000
26.886444	16.306416	-1.769888	18.000032	741.200737	1185.000000
26.916073	16.251182	-1.769888	18.000032	738.690103	1188.000000
26.947819	16.314753	-1.769888	18.000032	741.579701	1191.000000
26.975332	16.292868	-1.769514	18.000032	740.584922	1194.000000
27.009194	16.305374	-1.769888	18.000032	741.153367	1197.000000
27.038823	16.176147	-1.769701	18.000032	735.279431	1200.000000
27.066336	16.314753	-1.769888	18.000032	741.579701	1203.000000
27.098081	16.309543	-1.769514	18.000032	741.342849	1206.000000
27.127710	16.327259	-1.769888	18.000032	742.148147	1209.000000
27.157340	16.299121	-1.769888	18.000032	740.869144	1212.000000
27.186969	16.366861	-1.769701	18.000032	743.948224	1215.000000
27.216598	16.373114	-1.769888	18.000032	744.232446	1218.000000
27.248344	16.378325	-1.769888	18.000032	744.469299	1221.000000
27.277973	16.388746	-1.769514	18.000032	744.943003	1224.000000
27.309718	16.249098	-1.769888	18.000032	738.595363	1227.000000
27.337231	16.349144	-1.769888	18.000032	743.142926	1230.000000
27.366860	16.331428	-1.770262	18.000032	742.337628	1233.000000
27.394373	16.392915	-1.769888	18.000032	745.132485	1236.000000
27.428235	16.347060	-1.769888	18.000032	743.048185	1239.000000
27.457864	16.394999	-1.769888	18.000032	745.227226	1242.000000
27.487494	16.392915	-1.769701	18.000032	745.132485	1245.000000
27.517123	16.422095	-1.769888	18.000032	746.458858	1248.000000
27.546752	16.363734	-1.769888	18.000032	743.806112	1251.000000
27.576381	16.323091	-1.769888	18.000032	741.958665	1254.000000
27.606010	16.438769	-1.769888	18.000032	747.216785	1257.000000
27.637756	16.397083	-1.769888	18.000032	745.321967	1260.000000
27.667385	16.436685	-1.769327	18.000032	747.122044	1263.000000
27.699131	16.397083	-1.769514	18.000032	745.321967	1266.000000
27.728760	16.426263	-1.769701	18.000032	746.648340	1269.000000
27.758389	16.417926	-1.770075	18.000032	746.269376	1272.000000
27.788018	16.459612	-1.769888	18.000032	748.164194	1275.000000
27.817648	16.359566	-1.769514	18.000032	743.616631	1278.000000
27.847277	16.413758	-1.769701	18.000032	746.079894	1281.000000
27.876906	16.452317	-1.769888	18.000032	747.832601	1284.000000
27.906535	16.473160	-1.769888	18.000032	748.780010	1287.000000
27.936164	16.482540	-1.769888	18.000032	749.206344	1290.000000
27.970026	16.492961	-1.769888	18.000032	749.680049	1293.000000
27.997539	16.488792	-1.769888	18.000032	749.490567	1296.000000
28.027168	16.459612	-1.769701	18.000032	748.164194	1299.000000
28.054681	16.530478	-1.769888	18.000032	751.385385	1302.000000
28.088543	16.414800	-1.770449	18.000032	746.127265	1305.000000
28.113939	16.401252	-1.769514	18.000032	745.511449	1308.000000
28.147801	16.484624	-1.769888	18.000032	749.301085	1311.000000
28.175314	16.521099	-1.769888	18.000032	750.959051	1314.000000
28.207060	16.454402	-1.769888	18.000032	747.927342	1317.000000
28.236689	16.519015	-1.769888	18.000032	750.864310	1320.000000
28.266318	16.565912	-1.769888	18.000032	752.995980	1323.000000
28.298064	16.551321	-1.769701	18.000032	752.332794	1326.000000
28.325577	16.581544	-1.769888	18.000032	753.706537	1329.000000
28.359439	16.505467	-1.769701	18.000032	750.248494	1332.000000
28.393300	16.532563	-1.770075	18.000032	751.480126	1335.000000
28.414464	16.559659	-1.769888	18.000032	752.711758	1338.000000
28.446210	16.528394	-1.769888	18.000032	751.290644	1341.000000
28.473723	16.517973	-1.769888	18.000032	750.816939	1344.000000
28.507585	16.569038	-1.769888	18.000032	753.138092	1347.000000
28.537214	16.536731	-1.769888	18.000032	751.669608	1350.000000
28.564727	16.593007	-1.770262	18.000032	754.227612	1353.000000
28.596472	16.499214	-1.769888	18.000032	749.964271	1356.000000
28.626101	16.565912	-1.769701	18.000032	752.995980	1359.000000
28.657847	16.594050	-1.769888	18.000032	754.274982	1362.000000
28.687476	16.599260	-1.769888	18.000032	754.511835	1365.000000
28.717105	16.620103	-1.769888	18.000032	755.459244	1368.000000
28.746735	16.561743	-1.769888	18.000032	752.806498	1371.000000
28.776364	16.609682	-1.769701	18.000032	754.985539	1374.000000
28.808109	16.626356	-1.769888	18.000032	755.743466	1377.000000
28.835622	16.605513	-1.769888	18.000032	754.796057	1380.000000
28.867368	16.546111	-1.769888	18.000032	752.095942	1383.000000
28.896997	16.616977	-1.769888	18.000032	755.317132	1386.000000
28.924510	16.606555	-1.769888	18.000032	754.843428	1389.000000
28.956255	16.644073	-1.769701	18.000032	756.548764	1392.000000
28.985884	16.643031	-1.769888	18.000032	756.501394	1395.000000
29.015514	16.647199	-1.769888	18.000032	756.690876	1398.000000
29.045143	16.668042	-1.769888	18.000032	757.638285	1401.000000
29.074772	16.654494	-1.769888	18.000032	757.022469	1404.000000
29.108634	16.676379	-1.769701	18.000032	758.017248	1407.000000
29.138263	16.588839	-1.769888	18.000032	754.038130	1410.000000
29.167892	16.637820	-1.769701	18.000032	756.264541	1413.000000
29.195405	16.651368	-1.769888	18.000032	756.880357	1416.000000
29.227151	16.668042	-1.769888	18.000032	757.638285	1419.000000
29.256780	16.630525	-1.769701	18.000032	755.932948	1422.000000
29.286409	16.680548	-1.769888	18.000032	758.206730	1425.000000
29.316038	16.678464	-1.769701	18.000032	758.111989	1428.000000
29.345668	16.768089	-1.769888	18.000032	762.185848	1431.000000
29.375297	16.726403	-1.769888	18.000032	760.291030	1434.000000
29.409159	16.646157	-1.769701	18.000032	756.643505	1437.000000
29.436672	16.701391	-1.769888	18.000032	759.154139	1440.000000
29.466301	16.680548	-1.769888	18.000032	758.206730	1443.000000
29.495930	16.735782	-1.769514	18.000032	760.717364	1446.000000
29.527676	16.678464	-1.769888	18.000032	758.111989	1449.000000
29.557305	16.718065	-1.769701	18.000032	759.912066	1452.000000
29.584818	16.704518	-1.769888	18.000032	759.296250	1455.000000
29.616563	16.759751	-1.769888	18.000032	761.806884	1458.000000
29.646192	16.673253	-1.769701	18.000032	757.875137	1461.000000
29.680054	16.651368	-1.769888	18.000032	756.880357	1464.000000
29.705451	16.743077	-1.769701	18.000032	761.048957	1467.000000
29.735080	16.763920	-1.770075	18.000032	761.996366	1470.000000
29.766825	16.776426	-1.769888	18.000032	762.564812	1473.000000
29.794338	16.728487	-1.769701	18.000032	760.385771	1476.000000
29.823967	16.746204	-1.769701	18.000032	761.191069	1479.000000
29.857829	16.749330	-1.769888	18.000032	761.333180	1482.000000
29.885342	16.821238	-1.769888	18.000032	764.601741	1485.000000
29.917088	16.722234	-1.770262	18.000032	760.101548	1488.000000
29.944601	16.727445	-1.769888	18.000032	760.338400	1491.000000
29.974230	16.760794	-1.769701	18.000032	761.854255	1494.000000
30.005975	16.776426	-1.769514	18.000032	762.564812	1497.000000
30.035605	16.769131	-1.769514	18.000032	762.233219	1500.000000
30.063117	16.782679	-1.769888	18.000032	762.849034	1503.000000
30.094863	16.816028	-1.769888	18.000032	764.364889	1506.000000
30.126609	16.801437	-1.769888	18.000032	763.701703	1509.000000
30.154121	16.854587	-1.769888	18.000032	766.117596	1512.000000
30.187983	16.773299	-1.769888	18.000032	762.422700	1515.000000
30.213380	16.806648	-1.769888	18.000032	763.938555	1518.000000
30.245125	16.793100	-1.769888	18.000032	763.322739	1521.000000
30.276871	16.818112	-1.769888	18.000032	764.459630	1524.000000
30.304384	16.768089	-1.769701	18.000032	762.185848	1527.000000
30.331897	16.810817	-1.769888	18.000032	764.128037	1530.000000
30.365759	16.819154	-1.769888	18.000032	764.507000	1533.000000
30.393271	16.832702	-1.770075	18.000032	765.122816	1536.000000
30.425017	16.606555	-1.769888	18.000032	754.843428	1539.000000
30.454646	16.826449	-1.769888	18.000032	764.838593	1542.000000
30.486392	16.830618	-1.769701	18.000032	765.028075	1545.000000
30.513905	16.843123	-1.769514	18.000032	765.596521	1548.000000
30.545650	16.853545	-1.769888	18.000032	766.070225	1551.000000
30.575279	16.834786	-1.769888	18.000032	765.217557	1554.000000
30.607025	16.853545	-1.769701	18.000032	766.070225	1557.000000
30.634538	16.843123	-1.769701	18.000032	765.596521	1560.000000
30.664167	16.862924	-1.769701	18.000032	766.496559	1563.000000
30.695912	16.696180	-1.769888	18.000032	758.917287	1566.000000
30.725542	16.843123	-1.769888	18.000032	765.596521	1569.000000
30.755171	16.860840	-1.769888	18.000032	766.401818	1572.000000
30.784800	16.882725	-1.769888	18.000032	767.396598	1575.000000
30.814429	16.895231	-1.769888	18.000032	767.965043	1578.000000
30.844058	16.859798	-1.769888	18.000032	766.354448	1581.000000
30.875804	16.884809	-1.769514	18.000032	767.491339	1584.000000
30.903317	16.869177	-1.769701	18.000032	766.780782	1587.000000
30.937179	16.887936	-1.769888	18.000032	767.633450	1590.000000
30.966808	16.693054	-1.769888	18.000032	758.775175	1593.000000
30.994321	16.897315	-1.769888	18.000032	768.059784	1596.000000
31.023950	16.863966	-1.769888	18.000032	766.543930	1599.000000
31.053579	16.895231	-1.769514	18.000032	767.965043	1602.000000
31.085325	16.848334	-1.769701	18.000032	765.833373	1605.000000
31.114954	16.911905	-1.769701	18.000032	768.722971	1608.000000
31.144583	16.918158	-1.769888	18.000032	769.007193	1611.000000
31.174212	16.939001	-1.769888	18.000032	769.954602	1614.000000
31.205958	16.951507	-1.769888	18.000032	770.523048	1617.000000
31.229238	16.747246	-1.770262	18.000032	761.238439	1620.000000
31.263100	16.931706	-1.769701	18.000032	769.623009	1623.000000
31.292729	16.887936	-1.769514	18.000032	767.633450	1626.000000
31.324475	16.937959	-1.769888	18.000032	769.907232	1629.000000
31.354104	16.895231	-1.769888	18.000032	767.965043	1632.000000
31.385849	16.943170	-1.769888	18.000032	770.144084	1635.000000
31.415479	16.894189	-1.769888	18.000032	767.917673	1638.000000
31.445108	16.948381	-1.769888	18.000032	770.380936	1641.000000
31.474737	16.907737	-1.769888	18.000032	768.533489	1644.000000
31.508599	16.788932	-1.769514	18.000032	763.133257	1647.000000
31.536112	16.959844	-1.769888	18.000032	770.902011	1650.000000
31.567857	16.953591	-1.769888	18.000032	770.617789	1653.000000
31.595370	16.940043	-1.769888	18.000032	770.001973	1656.000000
31.622883	16.945254	-1.769888	18.000032	770.238825	1659.000000
31.654629	16.971308	-1.769888	18.000032	771.423086	1662.000000
31.686374	16.959844	-1.769888	18.000032	770.902011	1665.000000
31.713887	16.984856	-1.769701	18.000032	772.038902	1668.000000
31.745633	16.878557	-1.769514	18.000032	767.207116	1671.000000
31.779495	16.859798	-1.769888	18.000032	766.354448	1674.000000
31.802775	16.943170	-1.769701	18.000032	770.144084	1677.000000
31.832404	16.980687	-1.769514	18.000032	771.849420	1680.000000
31.864149	16.986940	-1.769701	18.000032	772.133643	1683.000000
31.891662	16.978603	-1.769701	18.000032	771.754680	1686.000000
31.925524	17.002572	-1.769701	18.000032	772.844200	1689.000000
31.955153	16.981729	-1.769701	18.000032	771.896791	1692.000000
31.984783	17.022373	-1.769888	18.000032	773.744239	1695.000000
32.012295	16.909821	-1.769888	18.000032	768.628230	1698.000000
32.037692	16.830618	-1.769888	18.000032	765.028075	1701.000000
32.071554	16.976519	-1.769701	18.000032	771.659939	1704.000000
32.105416	16.984856	-1.769701	18.000032	772.038902	1707.000000
32.135045	16.949423	-1.769888	18.000032	770.428307	1710.000000
32.164674	16.989024	-1.770262	18.000032	772.228384	1713.000000
32.194303	17.005699	-1.769888	18.000032	772.986311	1716.000000
32.223933	17.020289	-1.769701	18.000032	773.649498	1719.000000
32.253562	17.014036	-1.770075	18.000032	773.365275	1722.000000
32.283191	16.949423	-1.769888	18.000032	770.428307	1725.000000
32.312820	16.901484	-1.769888	18.000032	768.249266	1728.000000
32.342449	16.997362	-1.769701	18.000032	772.607348	1731.000000
32.374195	17.001530	-1.769701	18.000032	772.796829	1734.000000
32.405940	17.001530	-1.769514	18.000032	772.796829	1737.000000
32.435570	16.994235	-1.770075	18.000032	772.465236	1740.000000
32.463082	16.984856	-1.769888	18.000032	772.038902	1743.000000
32.494828	17.031753	-1.769701	18.000032	774.170573	1746.000000
32.520224	16.943170	-1.769701	18.000032	770.144084	1749.000000
32.554086	17.009867	-1.769888	18.000032	773.175793	1752.000000
32.592181	16.898357	-1.769701	18.000032	768.107155	1755.000000
32.613345	17.045301	-1.769701	18.000032	774.786389	1758.000000
32.645090	17.055722	-1.769701	18.000032	775.260093	1761.000000
32.672603	17.016120	-1.769701	18.000032	773.460016	1764.000000
32.704349	17.045301	-1.769888	18.000032	774.786389	1767.000000
32.733978	17.030710	-1.769514	18.000032	774.123202	1770.000000
32.763607	17.051553	-1.769888	18.000032	775.070611	1773.000000
32.795353	16.964013	-1.769888	18.000032	771.091493	1776.000000
32.822866	17.034879	-1.769888	18.000032	774.312684	1779.000000
32.854611	16.999446	-1.769888	18.000032	772.702089	1782.000000
32.884240	17.045301	-1.769514	18.000032	774.786389	1785.000000
32.913870	17.020289	-1.769888	18.000032	773.649498	1788.000000
32.943499	17.059891	-1.769327	18.000032	775.449575	1791.000000
32.973128	17.069270	-1.769888	18.000032	775.875909	1794.000000
33.002757	17.070312	-1.769701	18.000032	775.923279	1797.000000
33.032386	17.081776	-1.769888	18.000032	776.444354	1800.000000
33.059899	16.982772	-1.769888	18.000032	771.944161	1803.000000
33.093761	17.038005	-1.769888	18.000032	774.454795	1806.000000
33.123390	16.961929	-1.769888	18.000032	770.996752	1809.000000
33.153019	17.070312	-1.769888	18.000032	775.923279	1812.000000
33.182649	17.009867	-1.769701	18.000032	773.175793	1815.000000
33.214394	17.070312	-1.769888	18.000032	775.923279	1818.000000
33.244023	17.069270	-1.769888	18.000032	775.875909	1821.000000
33.273653	17.101577	-1.769514	18.000032	777.344393	1824.000000
33.303282	17.053638	-1.769888	18.000032	775.165352	1827.000000
33.330795	16.982772	-1.769701	18.000032	771.944161	1830.000000
33.364657	17.080734	-1.769888	18.000032	776.396984	1833.000000
33.394286	17.076565	-1.769701	18.000032	776.207502	1836.000000
33.423915	17.073439	-1.769514	18.000032	776.065391	1839.000000
33.451428	17.048427	-1.769701	18.000032	774.928500	1842.000000
33.483173	17.074481	-1.769701	18.000032	776.112761	1845.000000
33.512803	17.046343	-1.769888	18.000032	774.833759	1848.000000
33.544548	17.109914	-1.769888	18.000032	777.723357	1851.000000
33.574177	17.011952	-1.769701	18.000032	773.270534	1854.000000
33.608039	17.034879	-1.769888	18.000032	774.312684	1857.000000
33.633436	17.093239	-1.769701	18.000032	776.965429	1860.000000
33.660949	16.982772	-1.769701	18.000032	771.944161	1863.000000
33.694811	17.122420	-1.769888	18.000032	778.291802	1866.000000
33.722323	17.076565	-1.769888	18.000032	776.207502	1869.000000
33.756185	17.093239	-1.769888	18.000032	776.965429	1872.000000
33.783698	17.093239	-1.769514	18.000032	776.965429	1875.000000
33.813327	17.126588	-1.769888	18.000032	778.481284	1878.000000
33.845073	17.039048	-1.769888	18.000032	774.502166	1881.000000
33.870469	17.061975	-1.769701	18.000032	775.544316	1884.000000
33.902215	17.078649	-1.769701	18.000032	776.302243	1887.000000
33.933961	17.093239	-1.769701	18.000032	776.965429	1890.000000
33.963590	17.043216	-1.769701	18.000032	774.691648	1893.000000
33.993219	17.099492	-1.769888	18.000032	777.249652	1896.000000
34.022848	17.128673	-1.769888	18.000032	778.576025	1899.000000
34.054594	17.109914	-1.769701	18.000032	777.723357	1902.000000
34.084223	17.134925	-1.769888	18.000032	778.860247	1905.000000
34.111736	17.064059	-1.769888	18.000032	775.639057	1908.000000
34.143481	17.093239	-1.769888	18.000032	776.965429	1911.000000
34.173110	17.082818	-1.769701	18.000032	776.491725	1914.000000
34.204856	17.103661	-1.769888	18.000032	777.439134	1917.000000
34.232369	17.078649	-1.769888	18.000032	776.302243	1920.000000
34.264114	17.097408	-1.769888	18.000032	777.154911	1923.000000
34.293744	17.098450	-1.769514	18.000032	777.202282	1926.000000
34.323373	17.122420	-1.769888	18.000032	778.291802	1929.000000
34.353002	16.986940	-1.769701	18.000032	772.133643	1932.000000
34.382631	17.069270	-1.769514	18.000032	775.875909	1935.000000
34.412260	17.114082	-1.769701	18.000032	777.912838	1938.000000
34.444006	17.120335	-1.769514	18.000032	778.197061	1941.000000
34.473635	17.101577	-1.769514	18.000032	777.344393	1944.000000
34.501148	17.073439	-1.769888	18.000032	776.065391	1947.000000
34.532894	17.111998	-1.769888	18.000032	777.818097	1950.000000
34.562523	17.093239	-1.769514	18.000032	776.965429	1953.000000
34.594268	17.118251	-1.769701	18.000032	778.102320	1956.000000
34.617548	16.999446	-1.769701	18.000032	772.702089	1959.000000
34.653527	17.099492	-1.769514	18.000032	777.249652	1962.000000
34.683156	17.099492	-1.769701	18.000032	777.249652	1965.000000
34.712785	17.114082	-1.769701	18.000032	777.912838	1968.000000
34.733949	16.919200	-1.769888	18.000032	769.054564	1971.000000
34.772044	17.119293	-1.769888	18.000032	778.149691	1974.000000
34.803789	17.115125	-1.769888	18.000032	777.960209	1977.000000
34.833418	17.093239	-1.769701	18.000032	776.965429	1980.000000
34.863047	17.126588	-1.769888	18.000032	778.481284	1983.000000
34.894793	17.019247	-1.769514	18.000032	773.602127	1986.000000
34.922306	17.097408	-1.769514	18.000032	777.154911	1989.000000
34.951935	17.093239	-1.769888	18.000032	776.965429	1992.000000
34.981564	17.110956	-1.769888	18.000032	777.770727	1995.000000
35.011193	17.060933	-1.769888	18.000032	775.496945	1998.000000
35.042939	17.109914	-1.769701	18.000032	777.723357	2001.000000
35.072568	17.110956	-1.769888	18.000032	777.770727	2004.000000
35.102197	17.130757	-1.769888	18.000032	778.670766	2007.000000
35.131827	17.139094	-1.769888	18.000032	779.049729	2010.000000
35.165689	17.036963	-1.769701	18.000032	774.407425	2013.000000
35.191085	17.107830	-1.769888	18.000032	777.628616	2016.000000
35.222831	17.072396	-1.769888	18.000032	776.018020	2019.000000
35.254576	17.094282	-1.769888	18.000032	777.012800	2022.000000
35.284205	17.079691	-1.769888	18.000032	776.349613	2025.000000
35.313835	17.109914	-1.769888	18.000032	777.723357	2028.000000
35.343464	17.081776	-1.769888	18.000032	776.444354	2031.000000
35.373093	17.109914	-1.769888	18.000032	777.723357	2034.000000
35.398489	17.028626	-1.769888	18.000032	774.028461	2037.000000
35.436584	17.038005	-1.769888	18.000032	774.454795	2040.000000
35.461981	17.115125	-1.769888	18.000032	777.960209	2043.000000
35.495843	17.109914	-1.769701	18.000032	777.723357	2046.000000
35.523355	17.099492	-1.769888	18.000032	777.249652	2049.000000
35.550868	17.049469	-1.769888	18.000032	774.975870	2052.000000
35.582614	17.106787	-1.769888	18.000032	777.581245	2055.000000
35.610127	17.066144	-1.769888	18.000032	775.733798	2058.000000
35.643988	17.105745	-1.769888	18.000032	777.533875	2061.000000
35.669385	17.034879	-1.769888	18.000032	774.312684	2064.000000
35.699014	17.034879	-1.769701	18.000032	774.312684	2067.000000
35.732876	17.059891	-1.769514	18.000032	775.449575	2070.000000
35.762505	17.093239	-1.769701	18.000032	776.965429	2073.000000
35.792134	17.051553	-1.769514	18.000032	775.070611	2076.000000
35.821764	17.077607	-1.769701	18.000032	776.254873	2079.000000
35.853509	17.120335	-1.769701	18.000032	778.197061	2082.000000
35.881022	17.055722	-1.769701	18.000032	775.260093	2085.000000
35.912768	17.104703	-1.769701	18.000032	777.486504	2088.000000
35.944513	17.032795	-1.769701	18.000032	774.217943	2091.000000
35.972026	17.044258	-1.769701	18.000032	774.739018	2094.000000
36.003772	17.059891	-1.770262	18.000032	775.449575	2097.000000
36.033401	17.060933	-1.770262	18.000032	775.496945	2100.000000
36.063030	17.026542	-1.769701	18.000032	773.933720	2103.000000
36.092659	17.047385	-1.769514	18.000032	774.881129	2106.000000
36.122288	17.064059	-1.769514	18.000032	775.639057	2109.000000
36.151918	17.066144	-1.769701	18.000032	775.733798	2112.000000
36.181547	17.010910	-1.769701	18.000032	773.223164	2115.000000
36.211176	16.982772	-1.769514	18.000032	771.944161	2118.000000
36.240805	16.998404	-1.769701	18.000032	772.654718	2121.000000
36.270434	17.034879	-1.769514	18.000032	774.312684	2124.000000
36.302180	17.020289	-1.769701	18.000032	773.649498	2127.000000
36.331809	17.011952	-1.769888	18.000032	773.270534	2130.000000
36.361438	17.009867	-1.769888	18.000032	773.175793	2133.000000
36.393184	17.031753	-1.769701	18.000032	774.170573	2136.000000
36.422813	17.010910	-1.769888	18.000032	773.223164	2139.000000
36.452442	16.911905	-1.769888	18.000032	768.722971	2142.000000
36.486304	16.976519	-1.769701	18.000032	771.659939	2145.000000
36.511701	16.977561	-1.769888	18.000032	771.707309	2148.000000
36.541330	17.005699	-1.769701	18.000032	772.986311	2151.000000
36.573075	16.993193	-1.769701	18.000032	772.417866	2154.000000
36.600588	16.941086	-1.769701	18.000032	770.049343	2157.000000
36.632334	16.939001	-1.769888	18.000032	769.954602	2160.000000
36.661963	16.953591	-1.769888	18.000032	770.617789	2163.000000
36.691592	16.926495	-1.769888	18.000032	769.386157	2166.000000
36.723338	16.843123	-1.769701	18.000032	765.596521	2169.000000
36.752967	16.868135	-1.769701	18.000032	766.733412	2172.000000
36.780480	16.851461	-1.769888	18.000032	765.975484	2175.000000
36.810109	16.851461	-1.769888	18.000032	765.975484	2178.000000
36.841855	16.784763	-1.769888	18.000032	762.943775	2181.000000
36.871484	16.776426	-1.769701	18.000032	762.564812	2184.000000
36.903229	16.726403	-1.769888	18.000032	760.291030	2187.000000
36.930742	16.754541	-1.769888	18.000032	761.570032	2190.000000
36.962488	16.559659	-1.769514	18.000032	752.711758	2193.000000
36.994233	16.217833	-1.769888	18.000032	737.174249	2196.000000
37.019630	15.901020	-1.769888	18.000032	722.773631	2199.000000
37.053492	14.437841	-1.769514	18.000032	656.265516	2202.000000
37.081005	-0.022406	-1.769327	-6.488299	-1.018465	2205.000000
37.104285	-0.019801	-1.769514	-6.493209	-0.900039	2207.000000